Workbook

Sheet Geral
A1: UF | B1: INSTRUMENTO | C1: NÚMERO | D1: ANO | E1: PROCESSO SEI | F1: VENCIMENTO | G1: QUANT. TA | H1: SOLICITOU PRORROGAÇÃO 2025? | I1: VALOR GLOBAL | J1: VALOR REPASSE | K1: VALOR CONTRAPARTIDA | L1: REPASSE DESEMBOLSADO | M1: RENDIMENTO APROVADO | N1: SALDO DE RENDIMENTOS ATUAL | O1: SALDO RESIDUAL CAPITAL | P1: SALDO RESIDUAL CUSTEIO | Q1: CONTRAPARTIDA INTEGRALIZADA | R1: VALOR EXECUTADO GERAL | S1: VALOR PREVISTO OUVIDORIA | T1: VALOR PREVISTO CORREGEDORIA | U1: VALOR PREVISTO ESCOLA PENAL | V1: VALOR RELATIVO OUVIDORIA | W1: EXECUÇÃO OUVIDORIA | X1: EXECUÇÃO CORREGEDORIA | Y1: EXECUÇÃO ESCOLA PENAL | Z1: SALDO TOTAL DISPONÍVEL PARA DESTINAÇÃO À OUVIDORIA
A2: MT | B2: Convênio | C2: 937698 | D2: 2022 | E2: 08016024910202234 | F2: 46484 | G2: 3 | H2: SIM | I2: 392509.71 | J2: 356000 | K2: 36509.71 | L2: 356000 | N2: 53258.81 | O2: =IFERROR(SUMIFS(INDIRECT("'"&$A2&"'!M:M"),INDIRECT("'"&$A2&"'!F:F"),"CAPITAL"),0) -> 6831.55 | P2: =IFERROR(SUMIFS(INDIRECT("'"&$A2&"'!M:M"),INDIRECT("'"&$A2&"'!F:F"),"CUSTEIO"),0) -> 46000.39 | Q2: 36509.71 | R2: =N3 -> 26067.41 | S2: =IFERROR(SUMIFS(MT!$J:$J, MT!$E:$E, "OUVIDORIA", MT!$A:$A, $A2, MT!$C:$C, $C2), 0) -> 119503.74 | T2: =IFERROR(SUMIFS(MT!$J:$J, MT!$E:$E, "CORREGEDORIA", MT!$A:$A, $A2, MT!$C:$C, $C2), 0) -> 108156 | U2: =IFERROR(SUMIFS(MT!$J:$J, MT!$E:$E, "ESCOLA PENAL", MT!$A:$A, $A2, MT!$C:$C, $C2), 0) -> 164850 | V2: =IFERROR($S2/$I2,0) -> 0.3044606 | W2: =IF($S2<=0,0, SUMIFS(MT!$K:$K, MT!$E:$E, "OUVIDORIA", MT!$A:$A, $A2, MT!$C:$C, $C2) / $S2) -> 0.59108786 | X2: =IF($T2<=0,0, SUMIFS(MT!$K:$K, MT!$E:$E, "CORREGEDORIA", MT!$A:$A, $A2, MT!$C:$C, $C2) / $T2) -> 0.94277396 | Y2: =IF($U2<=0,0, SUMIFS(MT!$K:$K, MT!$E:$E, "ESCOLA PENAL", MT!$A:$A, $A2, MT!$C:$C, $C2) / $U2) -> 1 | Z2: =N2+O2+P2 -> 106090.75
A3: GO | B3: Convênio | C3: 937216 | D3: 2022 | E3: 08016024915202267 | F3: 46484 | G3: 1 | H3: SIM | I3: 388852.48 | J3: 384963.95 | K3: 3888.53 | L3: 384963.95 | N3: 26067.41 | O3: =IFERROR(SUMIFS(INDIRECT("'"&$A3&"'!M:M"),INDIRECT("'"&$A3&"'!F:F"),"CAPITAL"),0) -> 57725.21 | P3: =IFERROR(SUMIFS(INDIRECT("'"&$A3&"'!M:M"),INDIRECT("'"&$A3&"'!F:F"),"CUSTEIO"),0) -> 0 | Q3: 3888.53 | R3: =IFERROR(SUMIFS(GO!$K:$K, GO!$A:$A, $A3, GO!$C:$C, $C3), 0) -> 323819.27 | S3: =IFERROR(SUMIFS(GO!$J:$J, GO!$E:$E, "OUVIDORIA", GO!$A:$A, $A3, GO!$C:$C, $C3), 0) -> 106486 | T3: =IFERROR(SUMIFS(GO!$J:$J, GO!$E:$E, "CORREGEDORIA", GO!$A:$A, $A3, GO!$C:$C, $C3), 0) -> 87246.81 | U3: =IFERROR(SUMIFS(GO!$J:$J, GO!$E:$E, "ESCOLA PENAL", GO!$A:$A, $A3, GO!$C:$C, $C3), 0) -> 161086.33 | V3: =IFERROR($S3/$I3,0) -> 0.27384678 | W3: =IF($S3<=0,0, SUMIFS(GO!$K:$K, GO!$E:$E, "OUVIDORIA", GO!$A:$A, $A3, GO!$C:$C, $C3) / $S3) -> 1 | X3: =IF($T3<=0,0, SUMIFS(GO!$K:$K, GO!$E:$E, "CORREGEDORIA", GO!$A:$A, $A3, GO!$C:$C, $C3) / $T3) -> 0.73634979 | Y3: =IF($U3<=0,0, SUMIFS(GO!$K:$K, GO!$E:$E, "ESCOLA PENAL", GO!$A:$A, $A3, GO!$C:$C, $C3) / $U3) -> 0.95035438 | Z3: =N3+O3+P3 -> 83792.62
A4: PR | B4: Convênio | C4: 937871 | D4: 2022 | E4: 08016025090202206 | F4: 46484 | G4: 1 | H4: SIM | I4: 861700.16 | J4: 794355.17 | K4: 16211.33 | L4: 794355.17 | M4: 51133.66 | N4: 28124.68 | O4: =IFERROR(SUMIFS(INDIRECT("'"&$A4&"'!M:M"),INDIRECT("'"&$A4&"'!F:F"),"CAPITAL"),0) -> 45196.7 | P4: =IFERROR(SUMIFS(INDIRECT("'"&$A4&"'!M:M"),INDIRECT("'"&$A4&"'!F:F"),"CUSTEIO"),0) -> 0 | Q4: 16211.33 | R4: =IFERROR(SUMIFS(PR!$K:$K, PR!$A:$A, $A4, PR!$C:$C, $C4), 0) -> 485239.8 | S4: =IFERROR(SUMIFS(PR!$J:$J, PR!$E:$E, "OUVIDORIA", PR!$A:$A, $A4, PR!$C:$C, $C4), 0) -> 161317.98 | T4: =IFERROR(SUMIFS(PR!$J:$J, PR!$E:$E, "CORREGEDORIA", PR!$A:$A, $A4, PR!$C:$C, $C4), 0) -> 322820.85 | U4: =IFERROR(SUMIFS(PR!$J:$J, PR!$E:$E, "ESCOLA PENAL", PR!$A:$A, $A4, PR!$C:$C, $C4), 0) -> 334677.35 | V4: =IFERROR($S4/$I4,0) -> 0.18720895 | W4: =IF($S4<=0,0, SUMIFS(PR!$K:$K, PR!$E:$E, "OUVIDORIA", PR!$A:$A, $A4, PR!$C:$C, $C4) / $S4) -> 0.096053521 | X4: =IF($T4<=0,0, SUMIFS(PR!$K:$K, PR!$E:$E, "CORREGEDORIA", PR!$A:$A, $A4, PR!$C:$C, $C4) / $T4) -> 0.7990272 | Y4: =IF($U4<=0,0, SUMIFS(PR!$K:$K, PR!$E:$E, "ESCOLA PENAL", PR!$A:$A, $A4, PR!$C:$C, $C4) / $U4) -> 0.6328543 | Z4: =N4+O4+P4 -> 73321.38
A5: AM | B5: Convênio | C5: 937592 | D5: 2022 | E5: 08016024901202243 | F5: 46484 | G5: 1 | H5: SIM | I5: 300300 | J5: 300000 | K5: 300 | L5: 300000 | N5: 14404.99 | O5: =IFERROR(SUMIFS(INDIRECT("'"&$A5&"'!M:M"),INDIRECT("'"&$A5&"'!F:F"),"CAPITAL"),0) -> 47225.22 | P5: =IFERROR(SUMIFS(INDIRECT("'"&$A5&"'!M:M"),INDIRECT("'"&$A5&"'!F:F"),"CUSTEIO"),0) -> 29175 | Q5: 300 | R5: =IFERROR(SUMIFS(AM!$K$1:$K$24, AM!$A$1:$A$24, $A5, AM!$C$1:$C$24, $C5), 0) -> 223899.78 | S5: =IFERROR(SUMIFS(AM!$J$1:$J$24, AM!$E$1:$E$24, "OUVIDORIA", AM!$A$1:$A$24, $A5, AM!$C$1:$C$24, $C5), 0) -> 57507.98 | T5: =IFERROR(SUMIFS(AM!$J$1:$J$24, AM!$E$1:$E$24, "CORREGEDORIA", AM!$A$1:$A$24, $A5, AM!$C$1:$C$24, $C5), 0) -> 15129.7 | U5: =IFERROR(SUMIFS(AM!$J$1:$J$24, AM!$E$1:$E$24, "ESCOLA PENAL", AM!$A$1:$A$24, $A5, AM!$C$1:$C$24, $C5), 0) -> 227662.32 | V5: =IFERROR($S5/$I5,0) -> 0.19150176 | W5: =IF($S5<=0,0, SUMIFS(AM!$K$1:$K$24, AM!$E$1:$E$24, "OUVIDORIA", AM!$A$1:$A$24, $A5, AM!$C$1:$C$24, $C5) / $S5) -> 0.7953677 | X5: =IF($T5<=0,0, SUMIFS(AM!$K$1:$K$24, AM!$E$1:$E$24, "CORREGEDORIA", AM!$A$1:$A$24, $A5, AM!$C$1:$C$24, $C5) / $T5) -> 0.80371653 | Y5: =IF($U5<=0,0, SUMIFS(AM!$K$1:$K$24, AM!$E$1:$E$24, "ESCOLA PENAL", AM!$A$1:$A$24, $A5, AM!$C$1:$C$24, $C5) / $U5) -> 0.72914921 | Z5: =N5+O5+P5 -> 90805.21
A6: AC | B6: Convênio | C6: 937782 | D6: 2022 | E6: 08016024899202211 | F6: 46484 | G6: 1 | H6: SIM | I6: 396423.71 | J6: 396423.71 | K6: 5993.71 | L6: 150000 | N6: 21564.61 | O6: =IFERROR(SUMIFS(INDIRECT("'"&$A6&"'!M:M"),INDIRECT("'"&$A6&"'!F:F"),"CAPITAL"),0) -> 10533.1 | P6: =IFERROR(SUMIFS(INDIRECT("'"&$A6&"'!M:M"),INDIRECT("'"&$A6&"'!F:F"),"CUSTEIO"),0) -> 0 | Q6: 3593.71 | R6: =IFERROR(SUMIFS(AC!$K:$K, AC!$A:$A, $A6, AC!$C:$C, $C6), 0) -> 97141.55 | S6: =IFERROR(SUMIFS(AC!$J:$J, AC!$E:$E, "OUVIDORIA", AC!$A:$A, $A6, AC!$C:$C, $C6), 0) -> 242142.01 | T6: =IFERROR(SUMIFS(AC!$J:$J, AC!$E:$E, "CORREGEDORIA", AC!$A:$A, $A6, AC!$C:$C, $C6), 0) -> 44590.76 | U6: =IFERROR(SUMIFS(AC!$J:$J, AC!$E:$E, "ESCOLA PENAL", AC!$A:$A, $A6, AC!$C:$C, $C6), 0) -> 109681.1 | V6: =IFERROR($S6/$I6,0) -> 0.61081616 | W6: =IF($S6<=0,0, SUMIFS(AC!$K:$K, AC!$E:$E, "OUVIDORIA", AC!$A:$A, $A6, AC!$C:$C, $C6) / $S6) -> 0.14701596 | X6: =IF($T6<=0,0, SUMIFS(AC!$K:$K, AC!$E:$E, "CORREGEDORIA", AC!$A:$A, $A6, AC!$C:$C, $C6) / $T6) -> 0.85938813 | Y6: =IF($U6<=0,0, SUMIFS(AC!$K:$K, AC!$E:$E, "ESCOLA PENAL", AC!$A:$A, $A6, AC!$C:$C, $C6) / $U6) -> 0.21172326 | Z6: =N6+O6+P6 -> 32097.71
A7: MS | B7: Convênio | C7: 937265 | D7: 2022 | E7: 08016025017202226 | F7: 46484 | G7: 1 | H7: SIM | I7: 548000 | J7: 537040 | K7: 10960 | L7: 537040 | N7: 65876.01 | O7: =IFERROR(SUMIFS(INDIRECT("'"&$A7&"'!M:M"),INDIRECT("'"&$A7&"'!F:F"),"CAPITAL"),0) -> -79290.13 | P7: =IFERROR(SUMIFS(INDIRECT("'"&$A7&"'!M:M"),INDIRECT("'"&$A7&"'!F:F"),"CUSTEIO"),0) -> 0 | Q7: 10960 | R7: =IFERROR(SUMIFS(MS!$K:$K, MS!$A:$A, $A7, MS!$C:$C, $C7), 0) -> 311441.88 | S7: =IFERROR(SUMIFS(MS!$J:$J, MS!$E:$E, "OUVIDORIA", MS!$A:$A, $A7, MS!$C:$C, $C7), 0) -> 127595.47 | T7: =IFERROR(SUMIFS(MS!$J:$J, MS!$E:$E, "CORREGEDORIA", MS!$A:$A, $A7, MS!$C:$C, $C7), 0) -> 120294.2 | U7: =IFERROR(SUMIFS(MS!$J:$J, MS!$E:$E, "ESCOLA PENAL", MS!$A:$A, $A7, MS!$C:$C, $C7), 0) -> 300110.33 | V7: =IFERROR($S7/$I7,0) -> 0.23283845 | W7: =IF($S7<=0,0, SUMIFS(MS!$K:$K, MS!$E:$E, "OUVIDORIA", MS!$A:$A, $A7, MS!$C:$C, $C7) / $S7) -> 0.71172817 | X7: =IF($T7<=0,0, SUMIFS(MS!$K:$K, MS!$E:$E, "CORREGEDORIA", MS!$A:$A, $A7, MS!$C:$C, $C7) / $T7) -> 0.063471888 | Y7: =IF($U7<=0,0, SUMIFS(MS!$K:$K, MS!$E:$E, "ESCOLA PENAL", MS!$A:$A, $A7, MS!$C:$C, $C7) / $U7) -> 0.70971662 | Z7: =N7+O7+P7 -> -13414.12
A8: SP | B8: Convênio | C8: 938128 | D8: 2022 | E8: 08016025062202281 | F8: 46752 | G8: 1 | H8: SIM | I8: 3846559.5 | J8: 3769628.3 | K8: 76931.19 | L8: 3769628.3 | N8: 528436.85 | O8: =IFERROR(SUMIFS(INDIRECT("'"&$A8&"'!M:M"),INDIRECT("'"&$A8&"'!F:F"),"CAPITAL"),0) -> 887731.15 | P8: =IFERROR(SUMIFS(INDIRECT("'"&$A8&"'!M:M"),INDIRECT("'"&$A8&"'!F:F"),"CUSTEIO"),0) -> 400731.5 | Q8: 76931.19 | R8: =IFERROR(SUMIFS(SP!$K:$K, SP!$A:$A, $A8, SP!$C:$C, $C8), 0) -> 1068101.9 | S8: =IFERROR(SUMIFS(SP!$J:$J, SP!$E:$E, "OUVIDORIA", SP!$A:$A, $A8, SP!$C:$C, $C8), 0) -> 27513.73 | T8: =IFERROR(SUMIFS(SP!$J:$J, SP!$E:$E, "CORREGEDORIA", SP!$A:$A, $A8, SP!$C:$C, $C8), 0) -> 542449.85 | U8: =IFERROR(SUMIFS(SP!$J:$J, SP!$E:$E, "ESCOLA PENAL", SP!$A:$A, $A8, SP!$C:$C, $C8), 0) -> 2195566.9 | V8: =IFERROR($S8/$I8,0) -> 0.0071528154 | W8: =IF($S8<=0,0, SUMIFS(SP!$K:$K, SP!$E:$E, "OUVIDORIA", SP!$A:$A, $A8, SP!$C:$C, $C8) / $S8) -> 0.72996428 | X8: =IF($T8<=0,0, SUMIFS(SP!$K:$K, SP!$E:$E, "CORREGEDORIA", SP!$A:$A, $A8, SP!$C:$C, $C8) / $T8) -> 0.082606125 | Y8: =IF($U8<=0,0, SUMIFS(SP!$K:$K, SP!$E:$E, "ESCOLA PENAL", SP!$A:$A, $A8, SP!$C:$C, $C8) / $U8) -> 0.45692446 | Z8: =N8+O8+P8 -> 1816899.5
A9: MA | B9: Convênio | C9: 938277 | D9: 2022 | E9: 08016024893202235 | F9: 46484 | G9: 1 | H9: SIM | I9: 346697.9 | J9: 345652.9 | K9: 1045 | L9: 345652.9 | N9: 44991.21 | O9: =IFERROR(SUMIFS(INDIRECT("'"&$A9&"'!M:M"),INDIRECT("'"&$A9&"'!F:F"),"CAPITAL"),0) -> 7267.88 | P9: =IFERROR(SUMIFS(INDIRECT("'"&$A9&"'!M:M"),INDIRECT("'"&$A9&"'!F:F"),"CUSTEIO"),0) -> 41657.21 | Q9: 1045 | R9: =IFERROR(SUMIFS(MA!$K:$K, MA!$A:$A, $A9, MA!$C:$C, $C9), 0) -> 69485.85 | S9: =IFERROR(SUMIFS(MA!$J:$J, MA!$E:$E, "OUVIDORIA", MA!$A:$A, $A9, MA!$C:$C, $C9), 0) -> 105039.86 | T9: =IFERROR(SUMIFS(MA!$J:$J, MA!$E:$E, "CORREGEDORIA", MA!$A:$A, $A9, MA!$C:$C, $C9), 0) -> 108270.24 | U9: =IFERROR(SUMIFS(MA!$J:$J, MA!$E:$E, "ESCOLA PENAL", MA!$A:$A, $A9, MA!$C:$C, $C9), 0) -> 120195.47 | V9: =IFERROR($S9/$I9,0) -> 0.3029723 | W9: =IF($S9<=0,0, SUMIFS(MA!$K:$K, MA!$E:$E, "OUVIDORIA", MA!$A:$A, $A9, MA!$C:$C, $C9) / $S9) -> 0.13849124 | X9: =IF($T9<=0,0, SUMIFS(MA!$K:$K, MA!$E:$E, "CORREGEDORIA", MA!$A:$A, $A9, MA!$C:$C, $C9) / $T9) -> 0.058319257 | Y9: =IF($U9<=0,0, SUMIFS(MA!$K:$K, MA!$E:$E, "ESCOLA PENAL", MA!$A:$A, $A9, MA!$C:$C, $C9) / $U9) -> 0.40454528 | Z9: =N9+O9+P9 -> 93916.3
A10: PB | B10: Convênio | C10: 937818 | D10: 2022 | E10: 08016024920202270 | F10: 46484 | G10: 1 | H10: SIM | I10: 317757.09 | J10: 317439.34 | K10: 317.75 | L10: 317439.34 | N10: 51081.15 | O10: =IFERROR(SUMIFS(INDIRECT("'"&$A10&"'!M:M"),INDIRECT("'"&$A10&"'!F:F"),"CAPITAL"),0) -> 0 | P10: =IFERROR(SUMIFS(INDIRECT("'"&$A10&"'!M:M"),INDIRECT("'"&$A10&"'!F:F"),"CUSTEIO"),0) -> 0 | Q10: 317.75 | R10: =IFERROR(SUMIFS(PB!$K:$K, PB!$A:$A, $A10, PB!$C:$C, $C10), 0) -> 31085 | S10: =IFERROR(SUMIFS(PB!$J:$J, PB!$E:$E, "OUVIDORIA", PB!$A:$A, $A10, PB!$C:$C, $C10), 0) -> 27434.02 | T10: =IFERROR(SUMIFS(PB!$J:$J, PB!$E:$E, "CORREGEDORIA", PB!$A:$A, $A10, PB!$C:$C, $C10), 0) -> 95535.05 | U10: =IFERROR(SUMIFS(PB!$J:$J, PB!$E:$E, "ESCOLA PENAL", PB!$A:$A, $A10, PB!$C:$C, $C10), 0) -> 194788.02 | V10: =IFERROR($S10/$I10,0) -> 0.086336453 | W10: =IF($S10<=0,0, SUMIFS(PB!$K:$K, PB!$E:$E, "OUVIDORIA", PB!$A:$A, $A10, PB!$C:$C, $C10) / $S10) -> 0.096959906 | X10: =IF($T10<=0,0, SUMIFS(PB!$K:$K, PB!$E:$E, "CORREGEDORIA", PB!$A:$A, $A10, PB!$C:$C, $C10) / $T10) -> 0 | Y10: =IF($U10<=0,0, SUMIFS(PB!$K:$K, PB!$E:$E, "ESCOLA PENAL", PB!$A:$A, $A10, PB!$C:$C, $C10) / $U10) -> 0.14592787 | Z10: =N10+O10+P10 -> 51081.15
A11: PI | B11: Convênio | C11: 937780 | D11: 2022 | E11: 08016024995202251 | F11: 46484 | G11: 1 | H11: SIM | I11: 408371.26 | J11: 387952.7 | K11: 20418.56 | L11: 387952.7 | N11: 39771.71 | O11: =IFERROR(SUMIFS(INDIRECT("'"&$A11&"'!M:M"),INDIRECT("'"&$A11&"'!F:F"),"CAPITAL"),0) -> 5.03 | P11: =IFERROR(SUMIFS(INDIRECT("'"&$A11&"'!M:M"),INDIRECT("'"&$A11&"'!F:F"),"CUSTEIO"),0) -> 98.2 | Q11: 20418.56 | R11: =IFERROR(SUMIFS(PI!$K:$K, PI!$A:$A, $A11, PI!$C:$C, $C11), 0) -> 26473.8 | S11: =IFERROR(SUMIFS(PI!$J:$J, PI!$E:$E, "OUVIDORIA", PI!$A:$A, $A11, PI!$C:$C, $C11), 0) -> 44450.77 | T11: =IFERROR(SUMIFS(PI!$J:$J, PI!$E:$E, "CORREGEDORIA", PI!$A:$A, $A11, PI!$C:$C, $C11), 0) -> 169138 | U11: =IFERROR(SUMIFS(PI!$J:$J, PI!$E:$E, "ESCOLA PENAL", PI!$A:$A, $A11, PI!$C:$C, $C11), 0) -> 194777.46 | V11: =IFERROR($S11/$I11,0) -> 0.10884892 | W11: =IF($S11<=0,0, SUMIFS(PI!$K:$K, PI!$E:$E, "OUVIDORIA", PI!$A:$A, $A11, PI!$C:$C, $C11) / $S11) -> 0 | X11: =IF($T11<=0,0, SUMIFS(PI!$K:$K, PI!$E:$E, "CORREGEDORIA", PI!$A:$A, $A11, PI!$C:$C, $C11) / $T11) -> 0 | Y11: =IF($U11<=0,0, SUMIFS(PI!$K:$K, PI!$E:$E, "ESCOLA PENAL", PI!$A:$A, $A11, PI!$C:$C, $C11) / $U11) -> 0.13591819 | Z11: =N11+O11+P11 -> 39874.94
A12: RO | B12: Convênio | C12: 937917 | D12: 2022 | E12: 08016024924202258 | F12: 46484 | G12: 1 | H12: SIM | I12: 234072.01 | J12: 233837.94 | K12: 234.07 | L12: 233837.94 | N12: 29398.8 | O12: =IFERROR(SUMIFS(INDIRECT("'"&$A12&"'!M:M"),INDIRECT("'"&$A12&"'!F:F"),"CAPITAL"),0) -> 0 | P12: =IFERROR(SUMIFS(INDIRECT("'"&$A12&"'!M:M"),INDIRECT("'"&$A12&"'!F:F"),"CUSTEIO"),0) -> 15004.16 | Q12: 234.07 | R12: =IFERROR(SUMIFS(RO!$K:$K, RO!$A:$A, $A12, RO!$C:$C, $C12), 0) -> 13450 | S12: =IFERROR(SUMIFS(RO!$J:$J, RO!$E:$E, "OUVIDORIA", RO!$A:$A, $A12, RO!$C:$C, $C12), 0) -> 86734.48 | T12: =IFERROR(SUMIFS(RO!$J:$J, RO!$E:$E, "CORREGEDORIA", RO!$A:$A, $A12, RO!$C:$C, $C12), 0) -> 61475.44 | U12: =IFERROR(SUMIFS(RO!$J:$J, RO!$E:$E, "ESCOLA PENAL", RO!$A:$A, $A12, RO!$C:$C, $C12), 0) -> 85862.09 | V12: =IFERROR($S12/$I12,0) -> 0.37054614 | W12: =IF($S12<=0,0, SUMIFS(RO!$K:$K, RO!$E:$E, "OUVIDORIA", RO!$A:$A, $A12, RO!$C:$C, $C12) / $S12) -> 0.15507097 | X12: =IF($T12<=0,0, SUMIFS(RO!$K:$K, RO!$E:$E, "CORREGEDORIA", RO!$A:$A, $A12, RO!$C:$C, $C12) / $T12) -> 0 | Y12: =IF($U12<=0,0, SUMIFS(RO!$K:$K, RO!$E:$E, "ESCOLA PENAL", RO!$A:$A, $A12, RO!$C:$C, $C12) / $U12) -> 0 | Z12: =N12+O12+P12 -> 44402.96
A13: TO | B13: Convênio | C13: 937468 | D13: 2022 | E13: 08016024985202215 | F13: 46484 | G13: 1 | H13: SIM | I13: 265260.78 | J13: 259498.63 | K13: 5762.15 | L13: 259498.63 | N13: 26794.48 | O13: =IFERROR(SUMIFS(INDIRECT("'"&$A13&"'!M:M"),INDIRECT("'"&$A13&"'!F:F"),"CAPITAL"),0) -> -1118.97 | P13: =IFERROR(SUMIFS(INDIRECT("'"&$A13&"'!M:M"),INDIRECT("'"&$A13&"'!F:F"),"CUSTEIO"),0) -> 13594.58 | Q13: 5762.15 | R13: =IFERROR(SUMIFS(TO!$K:$K, TO!$A:$A, $A13, TO!$C:$C, $C13), 0) -> 17125.91 | S13: =IFERROR(SUMIFS(TO!$J:$J, TO!$E:$E, "OUVIDORIA", TO!$A:$A, $A13, TO!$C:$C, $C13), 0) -> 61018.73 | T13: =IFERROR(SUMIFS(TO!$J:$J, TO!$E:$E, "CORREGEDORIA", TO!$A:$A, $A13, TO!$C:$C, $C13), 0) -> 105826.66 | U13: =IFERROR(SUMIFS(TO!$J:$J, TO!$E:$E, "ESCOLA PENAL", TO!$A:$A, $A13, TO!$C:$C, $C13), 0) -> 104267.81 | V13: =IFERROR($S13/$I13,0) -> 0.23003299 | W13: =IF($S13<=0,0, SUMIFS(TO!$K:$K, TO!$E:$E, "OUVIDORIA", TO!$A:$A, $A13, TO!$C:$C, $C13) / $S13) -> 0.022026024 | X13: =IF($T13<=0,0, SUMIFS(TO!$K:$K, TO!$E:$E, "CORREGEDORIA", TO!$A:$A, $A13, TO!$C:$C, $C13) / $T13) -> 0.11305195 | Y13: =IF($U13<=0,0, SUMIFS(TO!$K:$K, TO!$E:$E, "ESCOLA PENAL", TO!$A:$A, $A13, TO!$C:$C, $C13) / $U13) -> 0.036617246 | Z13: =N13+O13+P13 -> 39270.09
A14: RJ | B14: Convênio | C14: 937817 | D14: 2022 | E14: 08016024874202217 | F14: 46484 | G14: 3 | H14: SIM | I14: 1583018.9 | J14: 1415055.8 | K14: 66621.71 | L14: 1415055.8 | M14: 101341.43 | N14: 85306.29 | O14: =IFERROR(SUMIFS(INDIRECT("'"&$A14&"'!M:M"),INDIRECT("'"&$A14&"'!F:F"),"CAPITAL"),0) -> 69167.97 | P14: =IFERROR(SUMIFS(INDIRECT("'"&$A14&"'!M:M"),INDIRECT("'"&$A14&"'!F:F"),"CUSTEIO"),0) -> 27463.27 | Q14: 66621.71 | R14: =IFERROR(SUMIFS(RJ!$K:$K, RJ!$A:$A, $A14, RJ!$C:$C, $C14), 0) -> 153079.45 | S14: =IFERROR(SUMIFS(RJ!$J:$J, RJ!$E:$E, "OUVIDORIA", RJ!$A:$A, $A14, RJ!$C:$C, $C14), 0) -> 323838.9 | T14: =IFERROR(SUMIFS(RJ!$J:$J, RJ!$E:$E, "CORREGEDORIA", RJ!$A:$A, $A14, RJ!$C:$C, $C14), 0) -> 601790.9 | U14: =IFERROR(SUMIFS(RJ!$J:$J, RJ!$E:$E, "ESCOLA PENAL", RJ!$A:$A, $A14, RJ!$C:$C, $C14), 0) -> 657205.77 | V14: =IFERROR($S14/$I14,0) -> 0.20457045 | W14: =IF($S14<=0,0, SUMIFS(RJ!$K:$K, RJ!$E:$E, "OUVIDORIA", RJ!$A:$A, $A14, RJ!$C:$C, $C14) / $S14) -> 0 | X14: =IF($T14<=0,0, SUMIFS(RJ!$K:$K, RJ!$E:$E, "CORREGEDORIA", RJ!$A:$A, $A14, RJ!$C:$C, $C14) / $T14) -> 0 | Y14: =IF($U14<=0,0, SUMIFS(RJ!$K:$K, RJ!$E:$E, "ESCOLA PENAL", RJ!$A:$A, $A14, RJ!$C:$C, $C14) / $U14) -> 0.23292469 | Z14: =N14+O14+P14 -> 181937.53
A15: AL | B15: Convênio | C15: 937221 | D15: 2022 | E15: 08016025053202290 | F15: 46484 | G15: 1 | H15: SIM | I15: 171603.5 | J15: 156000 | K15: 15600 | L15: 156000 | M15: 3.5 | N15: 17567.06 | O15: =IFERROR(SUMIFS(INDIRECT("'"&$A15&"'!M:M"),INDIRECT("'"&$A15&"'!F:F"),"CAPITAL"),0) -> 3.5 | P15: =IFERROR(SUMIFS(INDIRECT("'"&$A15&"'!M:M"),INDIRECT("'"&$A15&"'!F:F"),"CUSTEIO"),0) -> 0 | Q15: 15600 | R15: =IFERROR(SUMIFS(AL!$K:$K, AL!$A:$A, $A15, AL!$C:$C, $C15), 0) -> 0 | S15: =IFERROR(SUMIFS(AL!$J:$J, AL!$E:$E, "OUVIDORIA", AL!$A:$A, $A15, AL!$C:$C, $C15), 0) -> 39023.53 | T15: =IFERROR(SUMIFS(AL!$J:$J, AL!$E:$E, "CORREGEDORIA", AL!$A:$A, $A15, AL!$C:$C, $C15), 0) -> 63936.47 | U15: =IFERROR(SUMIFS(AL!$J:$J, AL!$E:$E, "ESCOLA PENAL", AL!$A:$A, $A15, AL!$C:$C, $C15), 0) -> 68640 | V15: =IFERROR($S15/$I15,0) -> 0.22740521 | W15: =IF($S15<=0,0, SUMIFS(AL!$K:$K, AL!$E:$E, "OUVIDORIA", AL!$A:$A, $A15, AL!$C:$C, $C15) / $S15) -> 0 | X15: =IF($T15<=0,0, SUMIFS(AL!$K:$K, AL!$E:$E, "CORREGEDORIA", AL!$A:$A, $A15, AL!$C:$C, $C15) / $T15) -> 0 | Y15: =IF($U15<=0,0, SUMIFS(AL!$K:$K, AL!$E:$E, "ESCOLA PENAL", AL!$A:$A, $A15, AL!$C:$C, $C15) / $U15) -> 0 | Z15: =N15+O15+P15 -> 17570.56
A16: SC | B16: Convênio | C16: 937783 | D16: 2022 | E16: 08016025010202212 | F16: 46484 | G16: 1 | H16: SIM | I16: 581020.22 | J16: 569399.82 | K16: 11620.4 | L16: 569399.82 | N16: 8232.23 | O16: =IFERROR(SUMIFS(INDIRECT("'"&$A16&"'!M:M"),INDIRECT("'"&$A16&"'!F:F"),"CAPITAL"),0) -> 18488.15 | P16: =IFERROR(SUMIFS(INDIRECT("'"&$A16&"'!M:M"),INDIRECT("'"&$A16&"'!F:F"),"CUSTEIO"),0) -> 92886.88 | Q16: 11620.4 | R16: =IFERROR(SUMIFS(SC!$K:$K, SC!$A:$A, $A16, SC!$C:$C, $C16), 0) -> 44897.82 | S16: =IFERROR(SUMIFS(SC!$J:$J, SC!$E:$E, "OUVIDORIA", SC!$A:$A, $A16, SC!$C:$C, $C16), 0) -> 140216.7 | T16: =IFERROR(SUMIFS(SC!$J:$J, SC!$E:$E, "CORREGEDORIA", SC!$A:$A, $A16, SC!$C:$C, $C16), 0) -> 147416.7 | U16: =IFERROR(SUMIFS(SC!$J:$J, SC!$E:$E, "ESCOLA PENAL", SC!$A:$A, $A16, SC!$C:$C, $C16), 0) -> 182011.85 | V16: =IFERROR($S16/$I16,0) -> 0.24132843 | W16: =IF($S16<=0,0, SUMIFS(SC!$K:$K, SC!$E:$E, "OUVIDORIA", SC!$A:$A, $A16, SC!$C:$C, $C16) / $S16) -> 0 | X16: =IF($T16<=0,0, SUMIFS(SC!$K:$K, SC!$E:$E, "CORREGEDORIA", SC!$A:$A, $A16, SC!$C:$C, $C16) / $T16) -> 0 | Y16: =IF($U16<=0,0, SUMIFS(SC!$K:$K, SC!$E:$E, "ESCOLA PENAL", SC!$A:$A, $A16, SC!$C:$C, $C16) / $U16) -> 0.24667526 | Z16: =N16+O16+P16 -> 119607.26

Sheet IND_PRORROG
A1: DADOS GERAIS | H1: INDICADORES GERAIS | N1: OUVIDORIA | P1: CORREGEDORIA | R1: ESCOLA PENAL
A2: UF | B2: NÚMERO | C2: VALOR GLOBAL | D2: VALOR EXECUTADO GERAL | E2: VALOR PREVISTO OUVIDORIA | F2: VALOR PREVISTO CORREGEDORIA | G2: VALOR PREVISTO ESCOLA PENAL | H2: IND 01 EXECUÇÃO | I2: IND 02 COMPLEX. DESPESA RESIDUAL | J2: IND 03 REGULAR. RSE | K2: IND 04 CONCENTRAÇÃO PROCESSUAL | L2: IND 05 MATURIDADE PROCESSUAL RESIDUAL | M2: IND 06 TEMPESTIVIDADE RELATIVA DA LICITAÇÃO | N2: IND 07 EXECUÇÃO OUVIDORIA | O2: IND 08 COMPLEX. DESPESA RESIDUAL | P2: IND 09 EXECUÇÃO CORREGEDORIA | Q2: IND 10 COMPLEX. DESPESA RESIDUAL | R2: IND 11 EXECUÇÃO ESCOLA PENAL | S2: IND 12 COMPLEX. DESPESA RESIDUAL
A3: MT | B3: 937698 | C3: 392509.71 | D3: =IFERROR(SUMIFS(MT!$K:$K, MT!$A:$A, $A3, MT!$C:$C, $B3), 0) -> 337453.87 | E3: =IFERROR(SUMIFS(MT!$J:$J, MT!$E:$E, "OUVIDORIA", MT!$A:$A, $A3, MT!$C:$C, $B3), 0) -> 119503.74 | F3: =IFERROR(SUMIFS(MT!$J:$J, MT!$E:$E, "CORREGEDORIA", MT!$A:$A, $A3, MT!$C:$C, $B3), 0) -> 108156 | G3: =IFERROR(SUMIFS(MT!$J:$J, MT!$E:$E, "ESCOLA PENAL", MT!$A:$A, $A3, MT!$C:$C, $B3), 0) -> 164850 | H3: =D3/C3 -> 0.85973381 | I3: Baixa Complexidade Apenas bens | J3: SIM | K3: Alta Concentração (Eficiente) Todos os itens pendentes estão agrupados em 1 único processo | L3: Alta Maturidade (Favorável) Licitação Publicada, Homologada ou Adesão a ARP confirmada | M3: Tempestivo Dentro de 12 meses do último ajuste | N3: =IF($E3<=0,0, SUMIFS(MT!$K:$K, MT!$E:$E, "OUVIDORIA", MT!$A:$A, $A3, MT!$C:$C, $B3) / $E3) -> 0.59108786 | O3: Baixa Complexidade Apenas bens | P3: =IF($F3<=0,0, SUMIFS(MT!$K:$K, MT!$E:$E, "CORREGEDORIA", MT!$A:$A, $A3, MT!$C:$C, $B3) / $F3) -> 0.94277396 | Q3: Baixa Complexidade Apenas bens | R3: =IF($G3<=0,0, SUMIFS(MT!$K:$K, MT!$E:$E, "ESCOLA PENAL", MT!$A:$A, $A3, MT!$C:$C, $B3) / $G3) -> 1 | S3: Baixa Complexidade Apenas bens
A4: GO | B4: 937216 | C4: 388852.48 | D4: =IFERROR(SUMIFS(GO!$K:$K, GO!$A:$A, $A4, GO!$C:$C, $B4), 0) -> 323819.27 | E4: =IFERROR(SUMIFS(GO!$J:$J, GO!$E:$E, "OUVIDORIA", GO!$A:$A, $A4, GO!$C:$C, $B4), 0) -> 106486 | F4: =IFERROR(SUMIFS(GO!$J:$J, GO!$E:$E, "CORREGEDORIA", GO!$A:$A, $A4, GO!$C:$C, $B4), 0) -> 87246.81 | G4: =IFERROR(SUMIFS(GO!$J:$J, GO!$E:$E, "ESCOLA PENAL", GO!$A:$A, $A4, GO!$C:$C, $B4), 0) -> 161086.33 | H4: =D4/C4 -> 0.83275609 | I4: Baixa Complexidade Apenas bens | J4: SIM | K4: Alta Concentração (Eficiente) Todos os itens pendentes estão agrupados em 1 único processo | L4: Alta Maturidade (Favorável) Licitação Publicada, Homologada ou Adesão a ARP confirmada | M4: Tempestivo Dentro de 12 meses do último ajuste | N4: =IF($E4<=0,0, SUMIFS(GO!$K:$K, GO!$E:$E, "OUVIDORIA", GO!$A:$A, $A4, GO!$C:$C, $B4) / $E4) -> 1 | O4: Baixa Complexidade Apenas bens | P4: =IF($F4<=0,0, SUMIFS(GO!$K:$K, GO!$E:$E, "CORREGEDORIA", GO!$A:$A, $A4, GO!$C:$C, $B4) / $F4) -> 0.73634979 | Q4: Baixa Complexidade Apenas bens | R4: =IF($G4<=0,0, SUMIFS(GO!$K:$K, GO!$E:$E, "ESCOLA PENAL", GO!$A:$A, $A4, GO!$C:$C, $B4) / $G4) -> 0.95035438 | S4: Baixa Complexidade Apenas bens
A5: PR | B5: 937871 | C5: 861700.16 | D5: =IFERROR(SUMIFS(PR!$K:$K, PR!$A:$A, $A5, PR!$C:$C, $B5), 0) -> 485239.8 | E5: =IFERROR(SUMIFS(PR!$J:$J, PR!$E:$E, "OUVIDORIA", PR!$A:$A, $A5, PR!$C:$C, $B5), 0) -> 161317.98 | F5: =IFERROR(SUMIFS(PR!$J:$J, PR!$E:$E, "CORREGEDORIA", PR!$A:$A, $A5, PR!$C:$C, $B5), 0) -> 322820.85 | G5: =IFERROR(SUMIFS(PR!$J:$J, PR!$E:$E, "ESCOLA PENAL", PR!$A:$A, $A5, PR!$C:$C, $B5), 0) -> 334677.35 | H5: =D5/C5 -> 0.56311908 | I5: Média Complexidade Majoritariamente bens | J5: SIM | K5: Dispersão Processual Necessidade de mais de 4 processos ou processos não abertos | L5: Alta Maturidade (Favorável) Licitação Publicada, Homologada ou Adesão a ARP confirmada | M5: Tempestivo Dentro de 12 meses do último ajuste | N5: =IF($E5<=0,0, SUMIFS(PR!$K:$K, PR!$E:$E, "OUVIDORIA", PR!$A:$A, $A5, PR!$C:$C, $B5) / $E5) -> 0.096053521 | O5: Média Complexidade Majoritariamente bens | P5: =IF($F5<=0,0, SUMIFS(PR!$K:$K, PR!$E:$E, "CORREGEDORIA", PR!$A:$A, $A5, PR!$C:$C, $B5) / $F5) -> 0.7990272 | Q5: Média Complexidade Majoritariamente bens | R5: =IF($G5<=0,0, SUMIFS(PR!$K:$K, PR!$E:$E, "ESCOLA PENAL", PR!$A:$A, $A5, PR!$C:$C, $B5) / $G5) -> 0.6328543 | S5: Baixa Complexidade Apenas bens
A6: AM | B6: 937592 | C6: 300300 | D6: =IFERROR(SUMIFS(AM!$K$1:$K$24, AM!$A$1:$A$24, $A6, AM!$C$1:$C$24, $B6), 0) -> 223899.78 | E6: =IFERROR(SUMIFS(AM!$J$1:$J$24, AM!$E$1:$E$24, "OUVIDORIA", AM!$A$1:$A$24, $A6, AM!$C$1:$C$24, $B6), 0) -> 57507.98 | F6: =IFERROR(SUMIFS(AM!$J$1:$J$24, AM!$E$1:$E$24, "CORREGEDORIA", AM!$A$1:$A$24, $A6, AM!$C$1:$C$24, $B6), 0) -> 15129.7 | G6: =IFERROR(SUMIFS(AM!$J$1:$J$24, AM!$E$1:$E$24, "ESCOLA PENAL", AM!$A$1:$A$24, $A6, AM!$C$1:$C$24, $B6), 0) -> 227662.32 | H6: =D6/C6 -> 0.74558701 | I6: Alta Complexidade Bens e serviços ou apenas serviços | J6: SIM | K6: Alta Concentração (Eficiente) Todos os itens pendentes estão agrupados em 1 único processo | L6: Média Maturidade Termo de Referência (TR) inserido ou em análise jurídica local | M6: Atrasado Mais de 18 meses desde o último ajuste | N6: =IF($E6<=0,0, SUMIFS(AM!$K$1:$K$24, AM!$E$1:$E$24, "OUVIDORIA", AM!$A$1:$A$24, $A6, AM!$C$1:$C$24, $B6) / $E6) -> 0.7953677 | O6: - | P6: =IF($F6<=0,0, SUMIFS(AM!$K$1:$K$24, AM!$E$1:$E$24, "CORREGEDORIA", AM!$A$1:$A$24, $A6, AM!$C$1:$C$24, $B6) / $F6) -> 0.80371653 | Q6: - | R6: =IF($G6<=0,0, SUMIFS(AM!$K$1:$K$24, AM!$E$1:$E$24, "ESCOLA PENAL", AM!$A$1:$A$24, $A6, AM!$C$1:$C$24, $B6) / $G6) -> 0.72914921 | S6: Alta Complexidade Bens e serviços ou apenas serviços
A7: RS | B7: 937925 | C7: 1273294.7 | D7: =IFERROR(SUMIFS(#REF!,#REF!, $A7,#REF!, $B7), 0) -> 0 | E7: =IFERROR(SUMIFS(#REF!,#REF!, "OUVIDORIA",#REF!, $A7,#REF!, $B7), 0) -> 0 | F7: =IFERROR(SUMIFS(#REF!,#REF!, "CORREGEDORIA",#REF!, $A7,#REF!, $B7), 0) -> 0 | G7: =IFERROR(SUMIFS(#REF!,#REF!, "ESCOLA PENAL",#REF!, $A7,#REF!, $B7), 0) -> 0 | H7: =D7/C7 -> 0 | I7: Alta Complexidade Bens e serviços ou apenas serviços | J7: SIM | K7: Dispersão Processual Necessidade de mais de 4 processos ou processos não abertos | L7: Baixa Maturidade (Risco) Processo não iniciado ou sem registro na Plataforma | M7: Atrasado Mais de 18 meses desde o último ajuste | N7: - | O7: - | P7: =IF($F7<=0,0, SUMIFS(#REF!,#REF!, "CORREGEDORIA",#REF!, $A7,#REF!, $B7) / $F7) -> 0 | Q7: Alta Complexidade Bens e serviços ou apenas serviços | R7: =IF($G7<=0,0, SUMIFS(#REF!,#REF!, "ESCOLA PENAL",#REF!, $A7,#REF!, $B7) / $G7) -> 0 | S7: Baixa Complexidade Apenas bens
A8: AC | B8: 937782 | C8: 153593.71 | D8: =IFERROR(SUMIFS(AC!$L:$L, AC!$A:$A, $A8, AC!$C:$C, $B8), 0) -> 299282.16 | E8: =IFERROR(SUMIFS(AC!$J:$J, AC!$E:$E, "OUVIDORIA", AC!$A:$A, $A8, AC!$C:$C, $B8), 0) -> 242142.01 | F8: =IFERROR(SUMIFS(AC!$J:$J, AC!$E:$E, "CORREGEDORIA", AC!$A:$A, $A8, AC!$C:$C, $B8), 0) -> 44590.76 | G8: =IFERROR(SUMIFS(AC!$J:$J, AC!$E:$E, "ESCOLA PENAL", AC!$A:$A, $A8, AC!$C:$C, $B8), 0) -> 109681.1 | H8: =D8/C8 -> 1.9485314 | I8: Média Complexidade Majoritariamente bens | J8: SIM | K8: Dispersão Processual Necessidade de mais de 4 processos ou processos não abertos | L8: Alta Maturidade (Favorável) Licitação Publicada, Homologada ou Adesão a ARP confirmada | M8: Tempestivo Dentro de 12 meses do último ajuste | N8: =IF($E8<=0,0, SUMIFS(AC!$K:$K, AC!$E:$E, "OUVIDORIA", AC!$A:$A, $A8, AC!$C:$C, $B8) / $E8) -> 0.14701596 | O8: Baixa Complexidade Apenas bens | P8: =IF($F8<=0,0, SUMIFS(AC!$K:$K, AC!$E:$E, "CORREGEDORIA", AC!$A:$A, $A8, AC!$C:$C, $B8) / $F8) -> 0.85938813 | Q8: Baixa Complexidade Apenas bens | R8: =IF($G8<=0,0, SUMIFS(AC!$K:$K, AC!$E:$E, "ESCOLA PENAL", AC!$A:$A, $A8, AC!$C:$C, $B8) / $G8) -> 0.21172326 | S8: Média Complexidade Majoritariamente bens
A9: MG | B9: 937878 | C9: 968858.15 | D9: =IFERROR(SUMIFS(#REF!,#REF!, $A9,#REF!, $B9), 0) -> 0 | E9: =IFERROR(SUMIFS(#REF!,#REF!, "OUVIDORIA",#REF!, $A9,#REF!, $B9), 0) -> 0 | F9: =IFERROR(SUMIFS(#REF!,#REF!, "CORREGEDORIA",#REF!, $A9,#REF!, $B9), 0) -> 0 | G9: =IFERROR(SUMIFS(#REF!,#REF!, "ESCOLA PENAL",#REF!, $A9,#REF!, $B9), 0) -> 0 | H9: =D9/C9 -> 0 | I9: Alta Complexidade Bens e serviços ou apenas serviços | J9: SIM | K9: Dispersão Processual Necessidade de mais de 4 processos ou processos não abertos | L9: Baixa Maturidade (Risco) Processo não iniciado ou sem registro na Plataforma | M9: Atenção 12 a 18 meses na fase interna. | N9: - | O9: - | P9: =IF($F9<=0,0, SUMIFS(#REF!,#REF!, "CORREGEDORIA",#REF!, $A9,#REF!, $B9) / $F9) -> 0 | Q9: Alta Complexidade Bens e serviços ou apenas serviços | R9: =IF($G9<=0,0, SUMIFS(#REF!,#REF!, "ESCOLA PENAL",#REF!, $A9,#REF!, $B9) / $G9) -> 0 | S9: Baixa Complexidade Apenas bens
A10: MS | B10: 937265 | C10: 548000 | D10: =IFERROR(SUMIFS(MS!$K:$K, MS!$A:$A, $A10, MS!$C:$C, $B10), 0) -> 311441.88 | E10: =IFERROR(SUMIFS(MS!$J:$J, MS!$E:$E, "OUVIDORIA", MS!$A:$A, $A10, MS!$C:$C, $B10), 0) -> 127595.47 | F10: =IFERROR(SUMIFS(MS!$J:$J, MS!$E:$E, "CORREGEDORIA", MS!$A:$A, $A10, MS!$C:$C, $B10), 0) -> 120294.2 | G10: =IFERROR(SUMIFS(MS!$J:$J, MS!$E:$E, "ESCOLA PENAL", MS!$A:$A, $A10, MS!$C:$C, $B10), 0) -> 300110.33 | H10: =D10/C10 -> 0.5683246 | I10: Baixa Complexidade Apenas bens | J10: SIM | K10: Dispersão Processual Necessidade de mais de 4 processos ou processos não abertos | L10: Alta Maturidade (Favorável) Licitação Publicada, Homologada ou Adesão a ARP confirmada | M10: Tempestivo Dentro de 12 meses do último ajuste | N10: =IF($E10<=0,0, SUMIFS(MS!$K:$K, MS!$E:$E, "OUVIDORIA", MS!$A:$A, $A10, MS!$C:$C, $B10) / $E10) -> 0.71172817 | O10: Baixa Complexidade Apenas bens | P10: =IF($F10<=0,0, SUMIFS(MS!$K:$K, MS!$E:$E, "CORREGEDORIA", MS!$A:$A, $A10, MS!$C:$C, $B10) / $F10) -> 0.063471888 | Q10: Baixa Complexidade Apenas bens | R10: =IF($G10<=0,0, SUMIFS(MS!$K:$K, MS!$E:$E, "ESCOLA PENAL", MS!$A:$A, $A10, MS!$C:$C, $B10) / $G10) -> 0.70971662 | S10: Baixa Complexidade Apenas bens
A11: SP | B11: 938128 | C11: 3846559.5 | D11: =IFERROR(SUMIFS(SP!$K:$K, SP!$A:$A, $A11, SP!$C:$C, $B11), 0) -> 1068101.9 | E11: =IFERROR(SUMIFS(SP!$J:$J, SP!$E:$E, "OUVIDORIA", SP!$A:$A, $A11, SP!$C:$C, $B11), 0) -> 27513.73 | F11: =IFERROR(SUMIFS(SP!$J:$J, SP!$E:$E, "CORREGEDORIA", SP!$A:$A, $A11, SP!$C:$C, $B11), 0) -> 542449.85 | G11: =IFERROR(SUMIFS(SP!$J:$J, SP!$E:$E, "ESCOLA PENAL", SP!$A:$A, $A11, SP!$C:$C, $B11), 0) -> 2195566.9 | H11: =D11/C11 -> 0.27767721 | I11: Alta Complexidade Bens e serviços ou apenas serviços | J11: SIM | K11: Dispersão Processual Necessidade de mais de 4 processos ou processos não abertos | L11: Alta Maturidade (Favorável) Licitação Publicada, Homologada ou Adesão a ARP confirmada | M11: Atenção 12 a 18 meses na fase interna. | N11: =IF($E11<=0,0, SUMIFS(SP!$K:$K, SP!$E:$E, "OUVIDORIA", SP!$A:$A, $A11, SP!$C:$C, $B11) / $E11) -> 0.72996428 | O11: Baixa Complexidade Apenas bens | P11: =IF($F11<=0,0, SUMIFS(SP!$K:$K, SP!$E:$E, "CORREGEDORIA", SP!$A:$A, $A11, SP!$C:$C, $B11) / $F11) -> 0.082606125 | Q11: Alta Complexidade Bens e serviços ou apenas serviços | R11: =IF($G11<=0,0, SUMIFS(SP!$K:$K, SP!$E:$E, "ESCOLA PENAL", SP!$A:$A, $A11, SP!$C:$C, $B11) / $G11) -> 0.45692446 | S11: Média Complexidade Majoritariamente bens
A12: MA | B12: 938277 | C12: 346697.9 | D12: =IFERROR(SUMIFS(MA!$K:$K, MA!$A:$A, $A12, MA!$C:$C, $B12), 0) -> 69485.85 | E12: =IFERROR(SUMIFS(MA!$J:$J, MA!$E:$E, "OUVIDORIA", MA!$A:$A, $A12, MA!$C:$C, $B12), 0) -> 105039.86 | F12: =IFERROR(SUMIFS(MA!$J:$J, MA!$E:$E, "CORREGEDORIA", MA!$A:$A, $A12, MA!$C:$C, $B12), 0) -> 108270.24 | G12: =IFERROR(SUMIFS(MA!$J:$J, MA!$E:$E, "ESCOLA PENAL", MA!$A:$A, $A12, MA!$C:$C, $B12), 0) -> 120195.47 | H12: =D12/C12 -> 0.20042189 | I12: Média Complexidade Majoritariamente bens | J12: NÃO | K12: Dispersão Processual Necessidade de mais de 4 processos ou processos não abertos | L12: Baixa Maturidade (Risco) Processo não iniciado ou sem registro na Plataforma | M12: Atrasado Mais de 18 meses desde o último ajuste | N12: =IF($E12<=0,0, SUMIFS(MA!$K:$K, MA!$E:$E, "OUVIDORIA", MA!$A:$A, $A12, MA!$C:$C, $B12) / $E12) -> 0.13849124 | O12: Baixa Complexidade Apenas bens | P12: =IF($F12<=0,0, SUMIFS(MA!$K:$K, MA!$E:$E, "CORREGEDORIA", MA!$A:$A, $A12, MA!$C:$C, $B12) / $F12) -> 0.058319257 | Q12: Média Complexidade Majoritariamente bens | R12: =IF($G12<=0,0, SUMIFS(MA!$K:$K, MA!$E:$E, "ESCOLA PENAL", MA!$A:$A, $A12, MA!$C:$C, $B12) / $G12) -> 0.40454528 | S12: Baixa Complexidade Apenas bens
A13: PB | B13: 937818 | C13: 317757.09 | D13: =IFERROR(SUMIFS(PB!$K:$K, PB!$A:$A, $A13, PB!$C:$C, $B13), 0) -> 31085 | E13: =IFERROR(SUMIFS(PB!$J:$J, PB!$E:$E, "OUVIDORIA", PB!$A:$A, $A13, PB!$C:$C, $B13), 0) -> 27434.02 | F13: =IFERROR(SUMIFS(PB!$J:$J, PB!$E:$E, "CORREGEDORIA", PB!$A:$A, $A13, PB!$C:$C, $B13), 0) -> 95535.05 | G13: =IFERROR(SUMIFS(PB!$J:$J, PB!$E:$E, "ESCOLA PENAL", PB!$A:$A, $A13, PB!$C:$C, $B13), 0) -> 194788.02 | H13: =D13/C13 -> 0.097826299 | I13: Alta Complexidade Bens e serviços ou apenas serviços | J13: NÃO | K13: Dispersão Processual Necessidade de mais de 4 processos ou processos não abertos | L13: Baixa Maturidade (Risco) Processo não iniciado ou sem registro na Plataforma | M13: Tempestivo Dentro de 12 meses do último ajuste | N13: =IF($E13<=0,0, SUMIFS(PB!$K:$K, PB!$E:$E, "OUVIDORIA", PB!$A:$A, $A13, PB!$C:$C, $B13) / $E13) -> 0.096959906 | O13: Baixa Complexidade Apenas bens | P13: =IF($F13<=0,0, SUMIFS(PB!$K:$K, PB!$E:$E, "CORREGEDORIA", PB!$A:$A, $A13, PB!$C:$C, $B13) / $F13) -> 0 | Q13: Alta Complexidade Bens e serviços ou apenas serviços | R13: =IF($G13<=0,0, SUMIFS(PB!$K:$K, PB!$E:$E, "ESCOLA PENAL", PB!$A:$A, $A13, PB!$C:$C, $B13) / $G13) -> 0.14592787 | S13: Baixa Complexidade Apenas bens
A14: PI | B14: 937780 | C14: 408371.26 | D14: =IFERROR(SUMIFS(PI!$K:$K, PI!$A:$A, $A14, PI!$C:$C, $B14), 0) -> 26473.8 | E14: =IFERROR(SUMIFS(PI!$J:$J, PI!$E:$E, "OUVIDORIA", PI!$A:$A, $A14, PI!$C:$C, $B14), 0) -> 44450.77 | F14: =IFERROR(SUMIFS(PI!$J:$J, PI!$E:$E, "CORREGEDORIA", PI!$A:$A, $A14, PI!$C:$C, $B14), 0) -> 169138 | G14: =IFERROR(SUMIFS(PI!$J:$J, PI!$E:$E, "ESCOLA PENAL", PI!$A:$A, $A14, PI!$C:$C, $B14), 0) -> 194777.46 | H14: =D14/C14 -> 0.064827775 | I14: Média Complexidade Majoritariamente bens | J14: SIM | K14: Dispersão Processual Necessidade de mais de 4 processos ou processos não abertos | L14: Baixa Maturidade (Risco) Processo não iniciado ou sem registro na Plataforma | M14: Atrasado Mais de 18 meses desde o último ajuste | N14: =IF($E14<=0,0, SUMIFS(PI!$K:$K, PI!$E:$E, "OUVIDORIA", PI!$A:$A, $A14, PI!$C:$C, $B14) / $E14) -> 0 | O14: Baixa Complexidade Apenas bens | P14: =IF($F14<=0,0, SUMIFS(PI!$K:$K, PI!$E:$E, "CORREGEDORIA", PI!$A:$A, $A14, PI!$C:$C, $B14) / $F14) -> 0 | Q14: Média Complexidade Majoritariamente bens | R14: =IF($G14<=0,0, SUMIFS(PI!$K:$K, PI!$E:$E, "ESCOLA PENAL", PI!$A:$A, $A14, PI!$C:$C, $B14) / $G14) -> 0.13591819 | S14: Baixa Complexidade Apenas bens
A15: RO | B15: 937917 | C15: 234072.01 | D15: =IFERROR(SUMIFS(RO!$K:$K, RO!$A:$A, $A15, RO!$C:$C, $B15), 0) -> 13450 | E15: =IFERROR(SUMIFS(RO!$J:$J, RO!$E:$E, "OUVIDORIA", RO!$A:$A, $A15, RO!$C:$C, $B15), 0) -> 86734.48 | F15: =IFERROR(SUMIFS(RO!$J:$J, RO!$E:$E, "CORREGEDORIA", RO!$A:$A, $A15, RO!$C:$C, $B15), 0) -> 61475.44 | G15: =IFERROR(SUMIFS(RO!$J:$J, RO!$E:$E, "ESCOLA PENAL", RO!$A:$A, $A15, RO!$C:$C, $B15), 0) -> 85862.09 | H15: =D15/C15 -> 0.05746095 | I15: Baixa Complexidade Apenas bens | J15: SIM | K15: Dispersão Processual Necessidade de mais de 4 processos ou processos não abertos | L15: Baixa Maturidade (Risco) Processo não iniciado ou sem registro na Plataforma | M15: Atrasado Mais de 18 meses desde o último ajuste | N15: =IF($E15<=0,0, SUMIFS(RO!$K:$K, RO!$E:$E, "OUVIDORIA", RO!$A:$A, $A15, RO!$C:$C, $B15) / $E15) -> 0.15507097 | O15: Baixa Complexidade Apenas bens | P15: =IF($F15<=0,0, SUMIFS(RO!$K:$K, RO!$E:$E, "CORREGEDORIA", RO!$A:$A, $A15, RO!$C:$C, $B15) / $F15) -> 0 | Q15: Baixa Complexidade Apenas bens | R15: =IF($G15<=0,0, SUMIFS(RO!$K:$K, RO!$E:$E, "ESCOLA PENAL", RO!$A:$A, $A15, RO!$C:$C, $B15) / $G15) -> 0 | S15: Baixa Complexidade Apenas bens
A16: TO | B16: 937468 | C16: 265260.78 | D16: =IFERROR(SUMIFS(TO!$K:$K, TO!$A:$A, $A16, TO!$C:$C, $B16), 0) -> 17125.91 | E16: =IFERROR(SUMIFS(TO!$J:$J, TO!$E:$E, "OUVIDORIA", TO!$A:$A, $A16, TO!$C:$C, $B16), 0) -> 61018.73 | F16: =IFERROR(SUMIFS(TO!$J:$J, TO!$E:$E, "CORREGEDORIA", TO!$A:$A, $A16, TO!$C:$C, $B16), 0) -> 105826.66 | G16: =IFERROR(SUMIFS(TO!$J:$J, TO!$E:$E, "ESCOLA PENAL", TO!$A:$A, $A16, TO!$C:$C, $B16), 0) -> 104267.81 | H16: =D16/C16 -> 0.064562541 | I16: Baixa Complexidade Apenas bens | J16: NÃO | K16: Dispersão Processual Necessidade de mais de 4 processos ou processos não abertos | L16: Baixa Maturidade (Risco) Processo não iniciado ou sem registro na Plataforma | M16: Atrasado Mais de 18 meses desde o último ajuste | N16: =IF($E16<=0,0, SUMIFS(TO!$K:$K, TO!$E:$E, "OUVIDORIA", TO!$A:$A, $A16, TO!$C:$C, $B16) / $E16) -> 0.022026024 | O16: Baixa Complexidade Apenas bens | P16: =IF($F16<=0,0, SUMIFS(TO!$K:$K, TO!$E:$E, "CORREGEDORIA", TO!$A:$A, $A16, TO!$C:$C, $B16) / $F16) -> 0.11305195 | Q16: Baixa Complexidade Apenas bens | R16: =IF($G16<=0,0, SUMIFS(TO!$K:$K, TO!$E:$E, "ESCOLA PENAL", TO!$A:$A, $A16, TO!$C:$C, $B16) / $G16) -> 0.036617246 | S16: Baixa Complexidade Apenas bens
A17: RJ | B17: 937817 | C17: 1583018.9 | D17: =IFERROR(SUMIFS(RJ!$K:$K, RJ!$A:$A, $A17, RJ!$C:$C, $B17), 0) -> 153079.45 | E17: =IFERROR(SUMIFS(RJ!$J:$J, RJ!$E:$E, "OUVIDORIA", RJ!$A:$A, $A17, RJ!$C:$C, $B17), 0) -> 323838.9 | F17: =IFERROR(SUMIFS(RJ!$J:$J, RJ!$E:$E, "CORREGEDORIA", RJ!$A:$A, $A17, RJ!$C:$C, $B17), 0) -> 601790.9 | G17: =IFERROR(SUMIFS(RJ!$J:$J, RJ!$E:$E, "ESCOLA PENAL", RJ!$A:$A, $A17, RJ!$C:$C, $B17), 0) -> 657205.77 | H17: =D17/C17 -> 0.09670096 | I17: Baixa Complexidade Apenas bens | J17: SIM | K17: Dispersão Processual Necessidade de mais de 4 processos ou processos não abertos | L17: Alta Maturidade (Favorável) Licitação Publicada, Homologada ou Adesão a ARP confirmada | M17: Atrasado Mais de 18 meses desde o último ajuste | N17: =IF($E17<=0,0, SUMIFS(RJ!$K:$K, RJ!$E:$E, "OUVIDORIA", RJ!$A:$A, $A17, RJ!$C:$C, $B17) / $E17) -> 0 | O17: Baixa Complexidade Apenas bens | P17: =IF($F17<=0,0, SUMIFS(RJ!$K:$K, RJ!$E:$E, "CORREGEDORIA", RJ!$A:$A, $A17, RJ!$C:$C, $B17) / $F17) -> 0 | Q17: Baixa Complexidade Apenas bens | R17: =IF($G17<=0,0, SUMIFS(RJ!$K:$K, RJ!$E:$E, "ESCOLA PENAL", RJ!$A:$A, $A17, RJ!$C:$C, $B17) / $G17) -> 0.23292469 | S17: Baixa Complexidade Apenas bens
A18: SC | B18: 937783 | C18: 581020.22 | D18: =IFERROR(SUMIFS(SC!$K:$K, SC!$A:$A, $A18, SC!$C:$C, $B18), 0) -> 44897.82 | E18: =IFERROR(SUMIFS(SC!$J:$J, SC!$E:$E, "OUVIDORIA", SC!$A:$A, $A18, SC!$C:$C, $B18), 0) -> 140216.7 | F18: =IFERROR(SUMIFS(SC!$J:$J, SC!$E:$E, "CORREGEDORIA", SC!$A:$A, $A18, SC!$C:$C, $B18), 0) -> 147416.7 | G18: =IFERROR(SUMIFS(SC!$J:$J, SC!$E:$E, "ESCOLA PENAL", SC!$A:$A, $A18, SC!$C:$C, $B18), 0) -> 182011.85 | H18: =D18/C18 -> 0.077274109 | I18: Baixa Complexidade Apenas bens | J18: SIM | K18: Dispersão Processual Necessidade de mais de 4 processos ou processos não abertos | L18: Baixa Maturidade (Risco) Processo não iniciado ou sem registro na Plataforma | M18: Atrasado Mais de 18 meses desde o último ajuste | N18: =IF($E18<=0,0, SUMIFS(SC!$K:$K, SC!$E:$E, "OUVIDORIA", SC!$A:$A, $A18, SC!$C:$C, $B18) / $E18) -> 0 | O18: Baixa Complexidade Apenas bens | P18: =IF($F18<=0,0, SUMIFS(SC!$K:$K, SC!$E:$E, "CORREGEDORIA", SC!$A:$A, $A18, SC!$C:$C, $B18) / $F18) -> 0 | Q18: Baixa Complexidade Apenas bens | R18: =IF($G18<=0,0, SUMIFS(SC!$K:$K, SC!$E:$E, "ESCOLA PENAL", SC!$A:$A, $A18, SC!$C:$C, $B18) / $G18) -> 0.24667526 | S18: Alta Complexidade Bens e serviços ou apenas serviços
A19: AL | B19: 937221 | C19: 171603.5 | D19: =IFERROR(SUMIFS(AL!$K:$K, AL!$A:$A, $A19, AL!$C:$C, $B19), 0) -> 0 | E19: =IFERROR(SUMIFS(AL!$J:$J, AL!$E:$E, "OUVIDORIA", AL!$A:$A, $A19, AL!$C:$C, $B19), 0) -> 39023.53 | F19: =IFERROR(SUMIFS(AL!$J:$J, AL!$E:$E, "CORREGEDORIA", AL!$A:$A, $A19, AL!$C:$C, $B19), 0) -> 63936.47 | G19: =IFERROR(SUMIFS(AL!$J:$J, AL!$E:$E, "ESCOLA PENAL", AL!$A:$A, $A19, AL!$C:$C, $B19), 0) -> 68640 | H19: =D19/C19 -> 0 | I19: Alta Complexidade Bens e serviços ou apenas serviços | J19: SIM | K19: Dispersão Processual Necessidade de mais de 4 processos ou processos não abertos | L19: Alta Maturidade (Favorável) Licitação Publicada, Homologada ou Adesão a ARP confirmada | M19: Atrasado Mais de 18 meses desde o último ajuste | N19: =IF($E19<=0,0, SUMIFS(AL!$K:$K, AL!$E:$E, "OUVIDORIA", AL!$A:$A, $A19, AL!$C:$C, $B19) / $E19) -> 0 | O19: Baixa Complexidade Apenas bens | P19: =IF($F19<=0,0, SUMIFS(AL!$K:$K, AL!$E:$E, "CORREGEDORIA", AL!$A:$A, $A19, AL!$C:$C, $B19) / $F19) -> 0 | Q19: Baixa Complexidade Apenas bens | R19: =IF($G19<=0,0, SUMIFS(AL!$K:$K, AL!$E:$E, "ESCOLA PENAL", AL!$A:$A, $A19, AL!$C:$C, $B19) / $G19) -> 0 | S19: Média Complexidade Majoritariamente bens
A20: RN | B20: 937263 | C20: 191556.03 | D20: =IFERROR(SUMIFS(#REF!,#REF!, $A20,#REF!, $B20), 0) -> 0 | E20: =IFERROR(SUMIFS(#REF!,#REF!, "OUVIDORIA",#REF!, $A20,#REF!, $B20), 0) -> 0 | F20: =IFERROR(SUMIFS(#REF!,#REF!, "CORREGEDORIA",#REF!, $A20,#REF!, $B20), 0) -> 0 | G20: =IFERROR(SUMIFS(#REF!,#REF!, "ESCOLA PENAL",#REF!, $A20,#REF!, $B20), 0) -> 0 | H20: =D20/C20 -> 0 | I20: Baixa Complexidade Apenas bens | J20: SIM | K20: Alta Concentração (Eficiente) Todos os itens pendentes estão agrupados em 1 único processo | L20: Alta Maturidade (Favorável) Licitação Publicada, Homologada ou Adesão a ARP confirmada | M20: Tempestivo Dentro de 12 meses do último ajuste | N20: =IF($E20<=0,0, SUMIFS(#REF!,#REF!, "OUVIDORIA",#REF!, $A20,#REF!, $B20) / $E20) -> 0 | O20: Baixa Complexidade Apenas bens | P20: =IF($F20<=0,0, SUMIFS(#REF!,#REF!, "CORREGEDORIA",#REF!, $A20,#REF!, $B20) / $F20) -> 0 | Q20: Baixa Complexidade Apenas bens | R20: =IF($G20<=0,0, SUMIFS(#REF!,#REF!, "ESCOLA PENAL",#REF!, $A20,#REF!, $B20) / $G20) -> 0 | S20: Baixa Complexidade Apenas bens
A21: RR | B21: 937781 | C21: 300000 | D21: =IFERROR(SUMIFS(#REF!,#REF!, $A21,#REF!, $B21), 0) -> 0 | E21: =IFERROR(SUMIFS(#REF!,#REF!, "OUVIDORIA",#REF!, $A21,#REF!, $B21), 0) -> 0 | F21: =IFERROR(SUMIFS(#REF!,#REF!, "CORREGEDORIA",#REF!, $A21,#REF!, $B21), 0) -> 0 | G21: =IFERROR(SUMIFS(#REF!,#REF!, "ESCOLA PENAL",#REF!, $A21,#REF!, $B21), 0) -> 0 | H21: =D21/C21 -> 0 | I21: Média Complexidade Majoritariamente bens | J21: NÃO | K21: Dispersão Processual Necessidade de mais de 4 processos ou processos não abertos | L21: Baixa Maturidade (Risco) Processo não iniciado ou sem registro na Plataforma | M21: Atrasado Mais de 18 meses desde o último ajuste | N21: =IF($E21<=0,0, SUMIFS(#REF!,#REF!, "OUVIDORIA",#REF!, $A21,#REF!, $B21) / $E21) -> 0 | O21: Média Complexidade Majoritariamente bens | P21: =IF($F21<=0,0, SUMIFS(#REF!,#REF!, "CORREGEDORIA",#REF!, $A21,#REF!, $B21) / $F21) -> 0 | Q21: Média Complexidade Majoritariamente bens | R21: =IF($G21<=0,0, SUMIFS(#REF!,#REF!, "ESCOLA PENAL",#REF!, $A21,#REF!, $B21) / $G21) -> 0 | S21: Baixa Complexidade Apenas bens
A22: PA | B22: 938161 | C22: 300579 | D22: =IFERROR(SUMIFS(#REF!,#REF!, $A22,#REF!, $B22), 0) -> 0 | E22: =IFERROR(SUMIFS(#REF!,#REF!, "OUVIDORIA",#REF!, $A22,#REF!, $B22), 0) -> 0 | F22: =IFERROR(SUMIFS(#REF!,#REF!, "CORREGEDORIA",#REF!, $A22,#REF!, $B22), 0) -> 0 | G22: =IFERROR(SUMIFS(#REF!,#REF!, "ESCOLA PENAL",#REF!, $A22,#REF!, $B22), 0) -> 0 | H22: =D22/C22 -> 0 | I22: Baixa Complexidade Apenas bens | J22: SIM | K22: Média Concentração Os itens estão divididos em 2 a 3 processos distintos | L22: Média Maturidade Termo de Referência (TR) inserido ou em análise jurídica local | M22: Atrasado Mais de 18 meses desde o último ajuste | N22: - | O22: - | P22: =IF($F22<=0,0, SUMIFS(#REF!,#REF!, "CORREGEDORIA",#REF!, $A22,#REF!, $B22) / $F22) -> 0 | Q22: Baixa Complexidade Apenas bens | R22: =IF($G22<=0,0, SUMIFS(#REF!,#REF!, "ESCOLA PENAL",#REF!, $A22,#REF!, $B22) / $G22) -> 0 | S22: Baixa Complexidade Apenas bens

Sheet MT
A1: UF | B1: INSTRUMENTO | C1: NÚMERO | D1: ANO | E1: ÁREA | F1: NATUREZA | G1: DESCRIÇÃO | H1: QUANTIDADE | I1: VALOR UNITÁRIO | J1: VALOR TOTAL PREVISTO | K1: VALOR TOTAL EXECUTADO | L1: SALDO | M1: SALDO ECONOMICIDADE
A2: MT | B2: Convênio | C2: 937698 | D2: 2022 | E2: OUVIDORIA | F2: CUSTEIO | G2: Cartilhas, Capa: 29,7x42,2cm, 4x4 cores, | H2: 5700.0 | I2: 7.32 | J2: 41743 | K2: 33573 | L2: 8170 | M2: =IF(E2="N/A", J2, IF(OR(K2=0, ISBLANK(K2), K2=""), 0, J2-K2)) -> 8170
A3: MT | B3: Convênio | C3: 937698 | D3: 2022 | E3: OUVIDORIA | F3: CUSTEIO | G3: Serviço de confecção de Banner, 90x120cm | H3: 316.0 | I3: 75 | J3: 23700 | K3: 7997.96 | L3: 15702.04 | M3: =IF(E3="N/A", J3, IF(OR(K3=0, ISBLANK(K3), K3=""), 0, J3-K3)) -> 15702.04
A4: MT | B4: Convênio | C4: 937698 | D4: 2022 | E4: OUVIDORIA | F4: CUSTEIO | G4: Serviço de confecção de Folders, 45x45cm | H4: 5713.0 | I4: 4.12 | J4: 23556.6 | K4: 1428.25 | L4: 22128.35 | M4: =IF(E4="N/A", J4, IF(OR(K4=0, ISBLANK(K4), K4=""), 0, J4-K4)) -> 22128.35
A5: MT | B5: Convênio | C5: 937698 | D5: 2022 | E5: OUVIDORIA | F5: CAPITAL | G5: ** TA Contrapartida - Computador Desktop | H5: 4.0 | I5: 3462.23 | J5: 13848.91 | K5: 13848.91 | L5: 0 | M5: =IF(E5="N/A", J5, IF(OR(K5=0, ISBLANK(K5), K5=""), 0, J5-K5)) -> 0
A6: MT | B6: Convênio | C6: 937698 | D6: 2022 | E6: OUVIDORIA | F6: CAPITAL | G6: ** TA Contrapartida - Fone ouvido tipo: | H6: 5.0 | I6: 8.58 | J6: 42.88 | K6: 0 | L6: 42.88 | M6: =IF(E6="N/A", J6, IF(OR(K6=0, ISBLANK(K6), K6=""), 0, J6-K6)) -> 0
A7: MT | B7: Convênio | C7: 937698 | D7: 2022 | E7: OUVIDORIA | F7: CAPITAL | G7: Celulares smartphone, 128gb-5g - octa-co | H7: 1.0 | I7: 2057.93 | J7: 2057.93 | K7: 1743 | L7: 314.93 | M7: =IF(E7="N/A", J7, IF(OR(K7=0, ISBLANK(K7), K7=""), 0, J7-K7)) -> 314.93
A8: MT | B8: Convênio | C8: 937698 | D8: 2022 | E8: OUVIDORIA | F8: CAPITAL | G8: Fone ouvido tipo: fechado, dinâmico , im | H8: 5.0 | I8: 170.42 | J8: 852.12 | K8: 895 | L8: -42.88 | M8: =IF(E8="N/A", J8, IF(OR(K8=0, ISBLANK(K8), K8=""), 0, J8-K8)) -> -42.88
A9: MT | B9: Convênio | C9: 937698 | D9: 2022 | E9: OUVIDORIA | F9: CAPITAL | G9: Webcan Full HD para chamadas e gravações | H9: 4.0 | I9: 545.26 | J9: 2181.05 | L9: 2181.05 | M9: =IF(E9="N/A", J9, IF(OR(K9=0, ISBLANK(K9), K9=""), 0, J9-K9)) -> 0
A10: MT | B10: Convênio | C10: 937698 | D10: 2022 | E10: OUVIDORIA | F10: CAPITAL | G10: ** Contrapartida - Computador Desktop Bá | H10: 4.0 | I10: 1996.92 | J10: 7987.69 | K10: 7987.69 | L10: 0 | M10: =IF(E10="N/A", J10, IF(OR(K10=0, ISBLANK(K10), K10=""), 0, J10-K10)) -> 0
A11: MT | B11: Convênio | C11: 937698 | D11: 2022 | E11: ESCOLA PENAL | F11: CAPITAL | G11: ** - Contrapartida - AMBULÂNCIA TIPO FIO | H11: 1.0 | I11: 164850 | J11: 164850 | K11: 164850 | L11: 0 | M11: =IF(E11="N/A", J11, IF(OR(K11=0, ISBLANK(K11), K11=""), 0, J11-K11)) -> 0
A12: MT | B12: Convênio | C12: 937698 | D12: 2022 | E12: CORREGEDORIA | F12: CAPITAL | G12: Veículo transporte pessoal, câmbio: manu | H12: 1.0 | I12: 108156 | J12: 108156 | K12: 101966.66 | L12: 6189.31 | M12: =IF(E12="N/A", J12, IF(OR(K12=0, ISBLANK(K12), K12=""), 0, J12-K12)) -> 6189.34
A13: MT | B13: Convênio | C13: 937698 | D13: 2022 | E13: OUVIDORIA | F13: CAPITAL | G13: Nobreak, alimentador automático de tensã | H13: 5.0 | I13: 706.71 | J13: 3533.56 | K13: 3163.4 | L13: 370.16 | M13: =IF(E13="N/A", J13, IF(OR(K13=0, ISBLANK(K13), K13=""), 0, J13-K13)) -> 370.16

Sheet GO
A1: UF | B1: INSTRUMENTO | C1: NÚMERO | D1: ANO | E1: ÁREA | F1: NATUREZA | G1: DESCRIÇÃO | H1: QUANTIDADE | I1: VALOR UNITÁRIO | J1: VALOR TOTAL PREVISTO | K1: VALOR TOTAL EXECUTADO | L1: SALDO | M1: SALDO ECONOMICIDADE | N1: TOTAL EXECUTADO OUVIDORIA | O1: % OUVIDORIA | P1: TOTAL EXECUTADO OUVIDORIA | Q1: % OUVIDORIA | R1: TOTAL EXECUTADO OUVIDORIA | S1: % OUVIDORIA
A2: GO | B2: Convênio | C2: 937216 | D2: 2022 | E2: ESCOLA PENAL | F2: CUSTEIO | G2: Cola para espuma acústica, cola de conta | H2: 10.0 | I2: 40.58 | J2: 405.8 | K2: 405.8 | M2: =IF(E2="N/A", J2, IF(OR(K2=0, ISBLANK(K2), K2=""), 0, J2-K2)) -> 0
A3: GO | B3: Convênio | C3: 937216 | D3: 2022 | E3: ESCOLA PENAL | F3: CUSTEIO | G3: Espuma Acústica Antichamas, 10 placas, 5 | H3: 10.0 | I3: 340 | J3: 3400 | K3: 3400 | M3: =IF(E3="N/A", J3, IF(OR(K3=0, ISBLANK(K3), K3=""), 0, J3-K3)) -> 0
A4: GO | B4: Convênio | C4: 937216 | D4: 2022 | E4: ESCOLA PENAL | F4: CUSTEIO | G4: Jogo de Pilhas recarregável 1000 Mah AAA | H4: 4.0 | I4: 29 | J4: 116 | K4: 116 | M4: =IF(E4="N/A", J4, IF(OR(K4=0, ISBLANK(K4), K4=""), 0, J4-K4)) -> 0
A5: GO | B5: Convênio | C5: 937216 | D5: 2022 | E5: ESCOLA PENAL | F5: CUSTEIO | G5: Jogo de Pilhas recarregável 2700 Mah AA | H5: 4.0 | I5: 16.6 | J5: 66.4 | K5: 66.4 | M5: =IF(E5="N/A", J5, IF(OR(K5=0, ISBLANK(K5), K5=""), 0, J5-K5)) -> 0
A6: GO | B6: Convênio | C6: 937216 | D6: 2022 | E6: ESCOLA PENAL | F6: CUSTEIO | G6: Munição CBC 5,56X45 COMUM M193 (TREINA) A | H6: 10000.0 | I6: 5.72 | J6: 57200 | K6: 57200 | M6: =IF(E6="N/A", J6, IF(OR(K6=0, ISBLANK(K6), K6=""), 0, J6-K6)) -> 0
A7: GO | B7: Convênio | C7: 937216 | D7: 2022 | E7: ESCOLA PENAL | F7: CUSTEIO | G7: Placas de isopor, forro isolamento termo | H7: 2.0 | I7: 121.76 | J7: 243.52 | K7: 243.52 | M7: =IF(E7="N/A", J7, IF(OR(K7=0, ISBLANK(K7), K7=""), 0, J7-K7)) -> 0
A8: GO | B8: Convênio | C8: 937216 | D8: 2022 | E8: N/A | F8: CAPITAL | G8: Saldo Remanescente - Conforme NOTA TÉCNI | H8: 1.0 | I8: 34033.34 | J8: 34033.34 | K8: 0 | L8: 34033.34 | M8: =IF(E8="N/A", J8, IF(OR(K8=0, ISBLANK(K8), K8=""), 0, J8-K8)) -> 34033.34
A9: GO | B9: Convênio | C9: 937216 | D9: 2022 | E9: ESCOLA PENAL | F9: CAPITAL | G9: Apresentador/Passador de slides, sem fio | H9: 3.0 | I9: 162.88 | J9: 488.64 | K9: 359.94 | L9: 128.7 | M9: =IF(E9="N/A", J9, IF(OR(K9=0, ISBLANK(K9), K9=""), 0, J9-K9)) -> 128.7
A10: GO | B10: Convênio | C10: 937216 | D10: 2022 | E10: ESCOLA PENAL | F10: CAPITAL | G10: Câmera DSLR: com lente EF-S 18-55mm, cap | H10: 1.0 | I10: 5343.33 | J10: 5343.33 | K10: 4679.99 | L10: 663.34 | M10: =IF(E10="N/A", J10, IF(OR(K10=0, ISBLANK(K10), K10=""), 0, J10-K10)) -> 663.34
A11: GO | B11: Convênio | C11: 937216 | D11: 2022 | E11: ESCOLA PENAL | F11: CAPITAL | G11: Câmera de Vídeo, Gravação de vídeos em F | H11: 1.0 | I11: 12064 | J11: 12064 | K11: 6249.99 | L11: 5814.01 | M11: =IF(E11="N/A", J11, IF(OR(K11=0, ISBLANK(K11), K11=""), 0, J11-K11)) -> 5814.01
A12: GO | B12: Convênio | C12: 937216 | D12: 2022 | E12: ESCOLA PENAL | F12: CAPITAL | G12: Estação de trabalho para edição de vídeo | H12: 2.0 | I12: 8390 | J12: 16780 | K12: 16600 | L12: 180 | M12: =IF(E12="N/A", J12, IF(OR(K12=0, ISBLANK(K12), K12=""), 0, J12-K12)) -> 180
A13: GO | B13: Convênio | C13: 937216 | D13: 2022 | E13: ESCOLA PENAL | F13: CAPITAL | G13: Gimbal Estabilizador para câmera DSLR, c | H13: 1.0 | I13: 2006.67 | J13: 2006.67 | K13: 1979.99 | L13: 26.68 | M13: =IF(E13="N/A", J13, IF(OR(K13=0, ISBLANK(K13), K13=""), 0, J13-K13)) -> 26.68
A14: GO | B14: Convênio | C14: 937216 | D14: 2022 | E14: ESCOLA PENAL | F14: CAPITAL | G14: Gravador de Aúdio Portátil, equipado com | H14: 2.0 | I14: 1357.82 | J14: 2715.64 | K14: 2715.62 | L14: 0.02 | M14: =IF(E14="N/A", J14, IF(OR(K14=0, ISBLANK(K14), K14=""), 0, J14-K14)) -> 0.02
A15: GO | B15: Convênio | C15: 937216 | D15: 2022 | E15: ESCOLA PENAL | F15: CAPITAL | G15: Headset, com transdutor dinâmico 53mm co | H15: 5.0 | I15: 425 | J15: 2125 | K15: 1900 | L15: 225 | M15: =IF(E15="N/A", J15, IF(OR(K15=0, ISBLANK(K15), K15=""), 0, J15-K15)) -> 225
A16: GO | B16: Convênio | C16: 937216 | D16: 2022 | E16: CORREGEDORIA | F16: CAPITAL | G16: Kit NVR com 4 câmeras, fonte de energia, | H16: 1.0 | I16: 956.28 | J16: 956.28 | K16: 937.99 | L16: 18.29 | M16: =IF(E16="N/A", J16, IF(OR(K16=0, ISBLANK(K16), K16=""), 0, J16-K16)) -> 18.29
A17: GO | B17: Convênio | C17: 937216 | D17: 2022 | E17: ESCOLA PENAL | F17: CAPITAL | G17: Kit Refletor Led Luz Fria para Estúdio c | H17: 1.0 | I17: 1155.22 | J17: 1155.22 | K17: 1155.21 | L17: 0.01 | M17: =IF(E17="N/A", J17, IF(OR(K17=0, ISBLANK(K17), K17=""), 0, J17-K17)) -> 0.01
A18: GO | B18: Convênio | C18: 937216 | D18: 2022 | E18: ESCOLA PENAL | F18: CAPITAL | G18: Kit Teleprompter (TP), Kit com Estrutura | H18: 1.0 | I18: 657.5 | J18: 657.5 | K18: 629.99 | L18: 27.51 | M18: =IF(E18="N/A", J18, IF(OR(K18=0, ISBLANK(K18), K18=""), 0, J18-K18)) -> 27.51
A19: GO | B19: Convênio | C19: 937216 | D19: 2022 | E19: ESCOLA PENAL | F19: CAPITAL | G19: Kit de tripé de vídeo profissional com c | H19: 1.0 | I19: 1189.91 | J19: 1189.91 | K19: 1169.99 | L19: 19.92 | M19: =IF(E19="N/A", J19, IF(OR(K19=0, ISBLANK(K19), K19=""), 0, J19-K19)) -> 19.92
A20: GO | B20: Convênio | C20: 937216 | D20: 2022 | E20: ESCOLA PENAL | F20: CAPITAL | G20: Lente zoom telefoto, distância focal 70- | H20: 1.0 | I20: 16640 | J20: 16640 | K20: 16640 | M20: =IF(E20="N/A", J20, IF(OR(K20=0, ISBLANK(K20), K20=""), 0, J20-K20)) -> 0
A21: GO | B21: Convênio | C21: 937216 | D21: 2022 | E21: ESCOLA PENAL | F21: CAPITAL | G21: Mesa de som com 6 canais, sendo 4 canais | H21: 1.0 | I21: 699.59 | J21: 699.59 | K21: 690 | L21: 9.59 | M21: =IF(E21="N/A", J21, IF(OR(K21=0, ISBLANK(K21), K21=""), 0, J21-K21)) -> 9.59
A22: GO | B22: Convênio | C22: 937216 | D22: 2022 | E22: ESCOLA PENAL | F22: CAPITAL | G22: Microfone super uni-direcional para uso | H22: 2.0 | I22: 242 | J22: 484 | K22: 419.98 | L22: 64.02 | M22: =IF(E22="N/A", J22, IF(OR(K22=0, ISBLANK(K22), K22=""), 0, J22-K22)) -> 64.02
A23: GO | B23: Convênio | C23: 937216 | D23: 2022 | E23: ESCOLA PENAL | F23: CAPITAL | G23: Monitor LED, mínimo 27, conexões DVI-D ( | H23: 4.0 | I23: 1805.33 | J23: 7221.32 | K23: 3270.64 | L23: 7221.32 | M23: =IF(E23="N/A", J23, IF(OR(K23=0, ISBLANK(K23), K23=""), 0, J23-K23)) -> 3950.68
A24: GO | B24: Convênio | C24: 937216 | D24: 2022 | E24: ESCOLA PENAL | F24: CAPITAL | G24: Monitor de Áudio, amplificador com potên | H24: 1.0 | I24: 890.65 | J24: 890.65 | K24: 849.99 | L24: 40.66 | M24: =IF(E24="N/A", J24, IF(OR(K24=0, ISBLANK(K24), K24=""), 0, J24-K24)) -> 40.66
A25: GO | B25: Convênio | C25: 937216 | D25: 2022 | E25: CORREGEDORIA | F25: CAPITAL | G25: Projetor 3.400 Lumens (no mínimo) Conexã | H25: 2.0 | I25: 4509.64 | J25: 9019.28 | K25: 7360 | L25: 1659.28 | M25: =IF(E25="N/A", J25, IF(OR(K25=0, ISBLANK(K25), K25=""), 0, J25-K25)) -> 1659.28
A26: GO | B26: Convênio | C26: 937216 | D26: 2022 | E26: ESCOLA PENAL | F26: CAPITAL | G26: Sistema de microfone headset (sem fio), | H26: 1.0 | I26: 1571.77 | J26: 1571.77 | K26: 1289.99 | L26: 281.78 | M26: =IF(E26="N/A", J26, IF(OR(K26=0, ISBLANK(K26), K26=""), 0, J26-K26)) -> 281.78
A27: GO | B27: Convênio | C27: 937216 | D27: 2022 | E27: ESCOLA PENAL | F27: CAPITAL | G27: Switcher de vídeo com barra de transição | H27: 1.0 | I27: 3800 | J27: 3800 | K27: 3200 | L27: 600 | M27: =IF(E27="N/A", J27, IF(OR(K27=0, ISBLANK(K27), K27=""), 0, J27-K27)) -> 600
A28: GO | B28: Convênio | C28: 937216 | D28: 2022 | E28: CORREGEDORIA | F28: CAPITAL | G28: TV 42, Recursos/Funcionalidades, Resolu | H28: 1.0 | I28: 1775.9 | J28: 1775.9 | K28: 1533.2 | L28: 242.7 | M28: =IF(E28="N/A", J28, IF(OR(K28=0, ISBLANK(K28), K28=""), 0, J28-K28)) -> 242.7
A29: GO | B29: Convênio | C29: 937216 | D29: 2022 | E29: ESCOLA PENAL | F29: CAPITAL | G29: TV 55, 4K UHD, mínimo 3 entradas HDMI 2. | H29: 2.0 | I29: 2753.03 | J29: 5506.06 | K29: 4666.8 | L29: 839.26 | M29: =IF(E29="N/A", J29, IF(OR(K29=0, ISBLANK(K29), K29=""), 0, J29-K29)) -> 839.26
A30: GO | B30: Convênio | C30: 937216 | D30: 2022 | E30: ESCOLA PENAL | F30: CAPITAL | G30: Tecido Fundo Infinito Verde, 3,00m Largu | H30: 2.0 | I30: 539.56 | J30: 1079.12 | K30: 1079.1 | L30: 0.02 | M30: =IF(E30="N/A", J30, IF(OR(K30=0, ISBLANK(K30), K30=""), 0, J30-K30)) -> 0.02
A31: GO | B31: Convênio | C31: 937216 | D31: 2022 | E31: CORREGEDORIA | F31: CAPITAL | G31: Webcam, Especificações: - Resolução máxi | H31: 12.0 | I31: 326.33 | J31: 3915.96 | K31: 3480 | L31: 435.96 | M31: =IF(E31="N/A", J31, IF(OR(K31=0, ISBLANK(K31), K31=""), 0, J31-K31)) -> 435.96
A32: GO | B32: Convênio | C32: 937216 | D32: 2022 | E32: ESCOLA PENAL | F32: CAPITAL | G32: Cartão de Memória Micro SD, 32Gb, com ad | H32: 4.0 | I32: 35.58 | J32: 142.32 | K32: 148 | L32: -5.68 | M32: =IF(E32="N/A", J32, IF(OR(K32=0, ISBLANK(K32), K32=""), 0, J32-K32)) -> -5.68
A33: GO | B33: Convênio | C33: 937216 | D33: 2022 | E33: ESCOLA PENAL | F33: CAPITAL | G33: Cartão de memória SD 32Gb, classe 10 | H33: 4.0 | I33: 37.83 | J33: 151.32 | K33: 139.96 | L33: 11.36 | M33: =IF(E33="N/A", J33, IF(OR(K33=0, ISBLANK(K33), K33=""), 0, J33-K33)) -> 11.36
A34: GO | B34: Convênio | C34: 937216 | D34: 2022 | E34: CORREGEDORIA | F34: CAPITAL | G34: HD Externo, Características: Capacidade: | H34: 9.0 | I34: 650 | J34: 5850 | K34: 5850 | M34: =IF(E34="N/A", J34, IF(OR(K34=0, ISBLANK(K34), K34=""), 0, J34-K34)) -> 0
A35: GO | B35: Convênio | C35: 937216 | D35: 2022 | E35: ESCOLA PENAL | F35: CAPITAL | G35: Kit mouse + teclado com fio, padrão ABNT2 | H35: 2.0 | I35: 73.33 | J35: 146.66 | K35: 115.98 | L35: 30.68 | M35: =IF(E35="N/A", J35, IF(OR(K35=0, ISBLANK(K35), K35=""), 0, J35-K35)) -> 30.68
A36: GO | B36: Convênio | C36: 937216 | D36: 2022 | E36: CORREGEDORIA | F36: CAPITAL | G36: Notebook, Com arquitetura x86 corporativ | H36: 6.0 | I36: 5146.52 | J36: 30879.12 | K36: 27000 | L36: 3879.12 | M36: =IF(E36="N/A", J36, IF(OR(K36=0, ISBLANK(K36), K36=""), 0, J36-K36)) -> 3879.12
A37: GO | B37: Convênio | C37: 937216 | D37: 2022 | E37: ESCOLA PENAL | F37: CAPITAL | G37: Notebook; Sistema Operacional: Proprietá | H37: 1.0 | I37: 3949.83 | J37: 3949.83 | K37: 3750 | L37: 3949.83 | M37: =IF(E37="N/A", J37, IF(OR(K37=0, ISBLANK(K37), K37=""), 0, J37-K37)) -> 199.83
A38: GO | B38: Convênio | C38: 937216 | D38: 2022 | E38: ESCOLA PENAL | F38: CAPITAL | G38: Tablet, Display Super AMOLED 14,6, TFT, | H38: 1.0 | I38: 5263.33 | J38: 5263.33 | K38: 10394.56 | L38: 83.33 | M38: =IF(E38="N/A", J38, IF(OR(K38=0, ISBLANK(K38), K38=""), 0, J38-K38)) -> -5131.23
A39: GO | B39: Convênio | C39: 937216 | D39: 2022 | E39: CORREGEDORIA | F39: CAPITAL | G39: Tablet, características mínimas: Process | H39: 4.0 | I39: 1827 | J39: 7308 | K39: 0 | L39: 7308 | M39: =IF(E39="N/A", J39, IF(OR(K39=0, ISBLANK(K39), K39=""), 0, J39-K39)) -> 0
A40: GO | B40: Convênio | C40: 937216 | D40: 2022 | E40: CORREGEDORIA | F40: CAPITAL | G40: Armário tipo Locker Roupeiro 20 Portas A | H40: 1.0 | I40: 1510.39 | J40: 1510.39 | K40: 1490 | L40: 20.39 | M40: =IF(E40="N/A", J40, IF(OR(K40=0, ISBLANK(K40), K40=""), 0, J40-K40)) -> 20.39
...

Sheet PR
A1: UF | B1: INSTRUMENTO | C1: NÚMERO | D1: ANO | E1: ÁREA | F1: NATUREZA | G1: DESCRIÇÃO | H1: QUANTIDADE | I1: VALOR UNITÁRIO | J1: VALOR TOTAL PREVISTO | K1: VALOR TOTAL EXECUTADO | L1: SALDO | M1: SALDO ECONOMICIDADE
A2: PR | B2: Convênio | C2: 937871 | D2: 2022 | E2: CORREGEDORIA | F2: CUSTEIO | G2: * Curso de Pós Graduação Processo Admini | H2: 20.0 | I2: 2555.28 | J2: 51105.53 | L2: =J2-K2 -> 51105.53 | M2: =IF(E2="N/A", J2, IF(OR(K2=0, ISBLANK(K2), K2=""), 0, J2-K2)) -> 0
A3: PR | B3: Convênio | C3: 937871 | D3: 2022 | E3: OUVIDORIA | F3: CUSTEIO | G3: Curso de Pós Graduação em Compliance e L | H3: 2.0 | I3: 4224.67 | J3: 8449.33 | L3: =J3-K3 -> 8449.33 | M3: =IF(E3="N/A", J3, IF(OR(K3=0, ISBLANK(K3), K3=""), 0, J3-K3)) -> 0
A4: PR | B4: Convênio | C4: 937871 | D4: 2022 | E4: CORREGEDORIA | F4: CAPITAL | G4: Ar Condicionado | H4: 2 | I4: 2195.72 | J4: =H4*I4 -> 4391.44 | L4: =J4-K4 -> 4391.44 | M4: =IF(E4="N/A", J4, IF(OR(K4=0, ISBLANK(K4), K4=""), 0, J4-K4)) -> 0
A5: PR | B5: Convênio | C5: 937871 | D5: 2022 | E5: ESCOLA PENAL | F5: CAPITAL | G5: Ar Condicionado | H5: 5 | I5: 2195.72 | J5: =H5*I5 -> 10978.6 | L5: =J5-K5 -> 10978.6 | M5: =IF(E5="N/A", J5, IF(OR(K5=0, ISBLANK(K5), K5=""), 0, J5-K5)) -> 0
A6: PR | B6: Convênio | C6: 937871 | D6: 2022 | E6: OUVIDORIA | F6: CAPITAL | G6: Ar Condicionado | H6: 1 | I6: 2195.72 | J6: =H6*I6 -> 2195.72 | L6: =J6-K6 -> 2195.72 | M6: =IF(E6="N/A", J6, IF(OR(K6=0, ISBLANK(K6), K6=""), 0, J6-K6)) -> 0
A7: PR | B7: Convênio | C7: 937871 | D7: 2022 | E7: CORREGEDORIA | F7: CAPITAL | G7: Gravador de Voz | H7: 12 | I7: 390.53 | J7: =H7*I7 -> 4686.36 | K7: 2951.88 | L7: =J7-K7 -> 1734.48 | M7: =IF(E7="N/A", J7, IF(OR(K7=0, ISBLANK(K7), K7=""), 0, J7-K7)) -> 1734.48
A8: PR | B8: Convênio | C8: 937871 | D8: 2022 | E8: OUVIDORIA | F8: CAPITAL | G8: Gravador de Voz | H8: 4 | I8: 390.53 | J8: =H8*I8 -> 1562.12 | K8: 983.96 | L8: =J8-K8 -> 578.16 | M8: =IF(E8="N/A", J8, IF(OR(K8=0, ISBLANK(K8), K8=""), 0, J8-K8)) -> 578.16
A9: PR | B9: Convênio | C9: 937871 | D9: 2022 | E9: N/A | F9: CAPITAL | G9: Saldo Remanescente de Capital 44 | H9: 1.0 | I9: 42884.02 | J9: 42884.02 | K9: 0 | L9: =J9-K9 -> 42884.02 | M9: =IF(E9="N/A", J9, IF(OR(K9=0, ISBLANK(K9), K9=""), 0, J9-K9)) -> 42884.02
A10: PR | B10: Convênio | C10: 937871 | D10: 2022 | E10: OUVIDORIA | F10: CAPITAL | G10: Televisão | H10: 1.0 | I10: 3351.47 | J10: 3351.47 | L10: =J10-K10 -> 3351.47 | M10: =IF(E10="N/A", J10, IF(OR(K10=0, ISBLANK(K10), K10=""), 0, J10-K10)) -> 0
A11: PR | B11: Convênio | C11: 937871 | D11: 2022 | E11: CORREGEDORIA | F11: CAPITAL | G11: Viva-Voz | H11: 4.0 | I11: 1112.78 | J11: 4451.12 | L11: =J11-K11 -> 4451.12 | M11: =IF(E11="N/A", J11, IF(OR(K11=0, ISBLANK(K11), K11=""), 0, J11-K11)) -> 0
