Workbook

Sheet Painel_Propostas
A1: ID_Proposta | B1: UF | C1: Estado | D1: Grupo | E1: Nº Proposta | F1: Ano | G1: Status Geral | H1: Órgão/Secretaria | I1: Nome do Secretário | J1: Cargo | K1: E-mail Gestor | L1: Responsável Técnico | M1: E-mail Resp. Técnico | N1: Valor Repasse | O1: Valor Contrapartida | P1: Valor Global | Q1: Ato normativo exigido? | R1: Ato normativo enviado? | S1: Fala.BR previsto no cronograma? | T1: DOC_PROJ_01 | U1: DOC_PROJ_02 | V1: DOC_PROJ_03 | W1: DOC_PROJ_04 | X1: DOC_PROJ_05 | Y1: DOC_FORM_01 | Z1: DOC_FORM_02 | AA1: DOC_FORM_03 | AB1: DOC_FORM_04 | AC1: DOC_FORM_05 | AD1: DOC_FORM_06 | AE1: DOC_FORM_07 | AF1: DOC_FORM_08 | AG1: DOC_FORM_09 | AH1: DOC_FORM_10 | AI1: DOC_FORM_11 | AJ1: DOC_FORM_12 | AK1: DOC_FORM_13 | AL1: Soma Plano Aplicação | AM1: Divergência Valor Global? | AN1: % Docs Projeto | AO1: % Docs Formalização | AP1: % Geral Docs | AQ1: Condição Suspensiva Pendente? | AR1: Última Atualização | AS1: Observações | AT1: Fonte/Origem
A2: AP-2026-001 | B2: AP | C2: Amapá | D2: Grupo 2 - Reforço institucional | E2: 900001/2026 | F2: 2026 | G2: Projeto aprovado | H2: Secretaria de Administração Penitenciária do Amapá | I2: Ana Paula Monteiro | J2: Secretário(a) estadual | K2: gabinete.ap@estado.simulado.gov.br | L2: Rafael Lima | M2: profor.ap@estado.simulado.gov.br | N2: 200000 | O2: 12000 | P2: =N2+O2 -> 212000 | Q2: Não | R2: Não se aplica | S2: Sim | T2: Sim | U2: Sim | V2: Sim | W2: Sim | X2: Sim | Y2: Sim | Z2: Sim | AA2: Sim | AB2: Sim | AC2: Sim | AD2: Sim | AE2: Sim | AF2: Sim | AG2: Sim | AH2: Sim | AI2: Não | AJ2: Não | AK2: Não | AL2: =SUM(Plano_AP!$K:$K) -> 212000 | AM2: =IF(ABS(AL2-P2)<0.01,"Não","Sim") -> Não | AN2: =COUNTIF(T2:X2,"Sim")/5 -> 1 | AO2: =COUNTIF(Y2:AK2,"Sim")/13 -> 0.76923077 | AP2: =(COUNTIF(T2:X2,"Sim")+COUNTIF(Y2:AK2,"Sim"))/18 -> 0.83333333 | AQ2: =IF(AND(Q2="Sim",R2<>"Sim"),"Sim","Não") -> Não | AR2: 46146 | AS2: Preenchimento simulado para modelagem da página de formalização. | AT2: Base simulada ONASP/PROFOR
A3: BA-2026-002 | B3: BA | C3: Bahia | D3: Grupo 2 - Reforço institucional | E3: 900002/2026 | F3: 2026 | G3: Em análise de formalização | H3: Secretaria de Administração Penitenciária e Ressocialização da Bahia | I3: Bruno Reis Almeida | J3: Secretário(a) estadual | K3: gabinete.ba@estado.simulado.gov.br | L3: Mariana Torres | M3: profor.ba@estado.simulado.gov.br | N3: 200000 | O3: 15000 | P3: =N3+O3 -> 215000 | Q3: Não | R3: Não se aplica | S3: Sim | T3: Sim | U3: Sim | V3: Sim | W3: Sim | X3: Sim | Y3: Sim | Z3: Sim | AA3: Sim | AB3: Sim | AC3: Sim | AD3: Sim | AE3: Sim | AF3: Sim | AG3: Não | AH3: Não | AI3: Não | AJ3: Não | AK3: Não | AL3: =SUM(Plano_BA!$K:$K) -> 215000 | AM3: =IF(ABS(AL3-P3)<0.01,"Não","Sim") -> Não | AN3: =COUNTIF(T3:X3,"Sim")/5 -> 1 | AO3: =COUNTIF(Y3:AK3,"Sim")/13 -> 0.61538462 | AP3: =(COUNTIF(T3:X3,"Sim")+COUNTIF(Y3:AK3,"Sim"))/18 -> 0.72222222 | AQ3: =IF(AND(Q3="Sim",R3<>"Sim"),"Sim","Não") -> Não | AR3: 46146 | AS3: Preenchimento simulado para modelagem da página de formalização. | AT3: Base simulada ONASP/PROFOR
A4: CE-2026-003 | B4: CE | C4: Ceará | D4: Grupo 2 - Reforço institucional | E4: 900003/2026 | F4: 2026 | G4: Em complementação pelo Estado | H4: Secretaria da Administração Penitenciária e Ressocialização do Ceará | I4: Camila Nogueira Lima | J4: Secretário(a) estadual | K4: gabinete.ce@estado.simulado.gov.br | L4: Paulo César | M4: profor.ce@estado.simulado.gov.br | N4: 200000 | O4: 10000 | P4: =N4+O4 -> 210000 | Q4: Não | R4: Não se aplica | S4: Sim | T4: Sim | U4: Sim | V4: Sim | W4: Sim | X4: Não | Y4: Sim | Z4: Sim | AA4: Sim | AB4: Sim | AC4: Sim | AD4: Não | AE4: Não | AF4: Não | AG4: Não | AH4: Não | AI4: Não | AJ4: Não | AK4: Não | AL4: =SUM(Plano_CE!$K:$K) -> 210000 | AM4: =IF(ABS(AL4-P4)<0.01,"Não","Sim") -> Não | AN4: =COUNTIF(T4:X4,"Sim")/5 -> 0.8 | AO4: =COUNTIF(Y4:AK4,"Sim")/13 -> 0.38461538 | AP4: =(COUNTIF(T4:X4,"Sim")+COUNTIF(Y4:AK4,"Sim"))/18 -> 0.5 | AQ4: =IF(AND(Q4="Sim",R4<>"Sim"),"Sim","Não") -> Não | AR4: 46146 | AS4: Preenchimento simulado para modelagem da página de formalização. | AT4: Base simulada ONASP/PROFOR
A5: DF-2026-004 | B5: DF | C5: Distrito Federal | D5: Grupo 2 - Reforço institucional | E5: 900004/2026 | F5: 2026 | G5: Apta à celebração | H5: Secretaria de Estado de Administração Penitenciária do Distrito Federal | I5: Daniel Freitas Rocha | J5: Secretário(a) estadual | K5: gabinete.df@estado.simulado.gov.br | L5: Lúcia Amaral | M5: profor.df@estado.simulado.gov.br | N5: 200000 | O5: 25000 | P5: =N5+O5 -> 225000 | Q5: Não | R5: Não se aplica | S5: Sim | T5: Sim | U5: Sim | V5: Sim | W5: Sim | X5: Sim | Y5: Sim | Z5: Sim | AA5: Sim | AB5: Sim | AC5: Sim | AD5: Sim | AE5: Sim | AF5: Sim | AG5: Sim | AH5: Sim | AI5: Sim | AJ5: Sim | AK5: Sim | AL5: =SUM(Plano_DF!$K:$K) -> 225000 | AM5: =IF(ABS(AL5-P5)<0.01,"Não","Sim") -> Não | AN5: =COUNTIF(T5:X5,"Sim")/5 -> 1 | AO5: =COUNTIF(Y5:AK5,"Sim")/13 -> 1 | AP5: =(COUNTIF(T5:X5,"Sim")+COUNTIF(Y5:AK5,"Sim"))/18 -> 1 | AQ5: =IF(AND(Q5="Sim",R5<>"Sim"),"Sim","Não") -> Não | AR5: 46146 | AS5: Preenchimento simulado para modelagem da página de formalização. | AT5: Base simulada ONASP/PROFOR
A6: ES-2026-005 | B6: ES | C6: Espírito Santo | D6: Grupo 2 - Reforço institucional | E6: 900005/2026 | F6: 2026 | G6: Proposta cadastrada | H6: Secretaria de Estado da Justiça do Espírito Santo | I6: Eduarda Siqueira Martins | J6: Secretário(a) estadual | K6: gabinete.es@estado.simulado.gov.br | L6: Renato Peixoto | M6: profor.es@estado.simulado.gov.br | N6: 200000 | O6: 10000 | P6: =N6+O6 -> 210000 | Q6: Não | R6: Não se aplica | S6: Não | T6: Sim | U6: Sim | V6: Sim | W6: Não | X6: Não | Y6: Sim | Z6: Sim | AA6: Não | AB6: Não | AC6: Não | AD6: Não | AE6: Não | AF6: Não | AG6: Não | AH6: Não | AI6: Não | AJ6: Não | AK6: Não | AL6: =SUM(Plano_ES!$K:$K) -> 210000 | AM6: =IF(ABS(AL6-P6)<0.01,"Não","Sim") -> Não | AN6: =COUNTIF(T6:X6,"Sim")/5 -> 0.6 | AO6: =COUNTIF(Y6:AK6,"Sim")/13 -> 0.15384615 | AP6: =(COUNTIF(T6:X6,"Sim")+COUNTIF(Y6:AK6,"Sim"))/18 -> 0.27777778 | AQ6: =IF(AND(Q6="Sim",R6<>"Sim"),"Sim","Não") -> Não | AR6: 46146 | AS6: Preenchimento simulado para modelagem da página de formalização. | AT6: Base simulada ONASP/PROFOR
A7: MG-2026-006 | B7: MG | C7: Minas Gerais | D7: Grupo 2 - Reforço institucional | E7: 900006/2026 | F7: 2026 | G7: Em análise técnica | H7: Secretaria de Estado de Justiça e Segurança Pública de Minas Gerais | I7: Fernando Costa Andrade | J7: Secretário(a) estadual | K7: gabinete.mg@estado.simulado.gov.br | L7: Aline Campos | M7: profor.mg@estado.simulado.gov.br | N7: 200000 | O7: 30000 | P7: =N7+O7 -> 230000 | Q7: Não | R7: Não se aplica | S7: Sim | T7: Sim | U7: Sim | V7: Sim | W7: Sim | X7: Não | Y7: Sim | Z7: Sim | AA7: Sim | AB7: Sim | AC7: Não | AD7: Não | AE7: Não | AF7: Não | AG7: Não | AH7: Não | AI7: Não | AJ7: Não | AK7: Não | AL7: =SUM(Plano_MG!$K:$K) -> 230000 | AM7: =IF(ABS(AL7-P7)<0.01,"Não","Sim") -> Não | AN7: =COUNTIF(T7:X7,"Sim")/5 -> 0.8 | AO7: =COUNTIF(Y7:AK7,"Sim")/13 -> 0.30769231 | AP7: =(COUNTIF(T7:X7,"Sim")+COUNTIF(Y7:AK7,"Sim"))/18 -> 0.44444444 | AQ7: =IF(AND(Q7="Sim",R7<>"Sim"),"Sim","Não") -> Não | AR7: 46146 | AS7: Preenchimento simulado para modelagem da página de formalização. | AT7: Base simulada ONASP/PROFOR
A8: PA-2026-007 | B8: PA | C8: Pará | D8: Grupo 1 - Condição suspensiva | E8: 900007/2026 | F8: 2026 | G8: Em complementação pelo Estado | H8: Secretaria de Estado de Administração Penitenciária do Pará | I8: Gabriela Sousa Pinto | J8: Secretário(a) estadual | K8: gabinete.pa@estado.simulado.gov.br | L8: Carlos Sena | M8: profor.pa@estado.simulado.gov.br | N8: 200000 | O8: 8000 | P8: =N8+O8 -> 208000 | Q8: Sim | R8: Não | S8: Sim | T8: Sim | U8: Sim | V8: Sim | W8: Sim | X8: Não | Y8: Sim | Z8: Sim | AA8: Sim | AB8: Sim | AC8: Sim | AD8: Não | AE8: Não | AF8: Não | AG8: Não | AH8: Não | AI8: Não | AJ8: Não | AK8: Não | AL8: =SUM(Plano_PA!$K:$K) -> 208000 | AM8: =IF(ABS(AL8-P8)<0.01,"Não","Sim") -> Não | AN8: =COUNTIF(T8:X8,"Sim")/5 -> 0.8 | AO8: =COUNTIF(Y8:AK8,"Sim")/13 -> 0.38461538 | AP8: =(COUNTIF(T8:X8,"Sim")+COUNTIF(Y8:AK8,"Sim"))/18 -> 0.5 | AQ8: =IF(AND(Q8="Sim",R8<>"Sim"),"Sim","Não") -> Sim | AR8: 46146 | AS8: Preenchimento simulado para modelagem da página de formalização. | AT8: Base simulada ONASP/PROFOR
A9: PE-2026-008 | B9: PE | C9: Pernambuco | D9: Grupo 2 - Reforço institucional | E9: 900008/2026 | F9: 2026 | G9: Projeto aprovado | H9: Secretaria de Administração Penitenciária e Ressocialização de Pernambuco | I9: Henrique Moraes Cavalcanti | J9: Secretário(a) estadual | K9: gabinete.pe@estado.simulado.gov.br | L9: Viviane Rocha | M9: profor.pe@estado.simulado.gov.br | N9: 200000 | O9: 14000 | P9: =N9+O9 -> 214000 | Q9: Não | R9: Não se aplica | S9: Sim | T9: Sim | U9: Sim | V9: Sim | W9: Sim | X9: Sim | Y9: Sim | Z9: Sim | AA9: Sim | AB9: Sim | AC9: Sim | AD9: Sim | AE9: Sim | AF9: Sim | AG9: Sim | AH9: Não | AI9: Não | AJ9: Não | AK9: Não | AL9: =SUM(Plano_PE!$K:$K) -> 214000 | AM9: =IF(ABS(AL9-P9)<0.01,"Não","Sim") -> Não | AN9: =COUNTIF(T9:X9,"Sim")/5 -> 1 | AO9: =COUNTIF(Y9:AK9,"Sim")/13 -> 0.69230769 | AP9: =(COUNTIF(T9:X9,"Sim")+COUNTIF(Y9:AK9,"Sim"))/18 -> 0.77777778 | AQ9: =IF(AND(Q9="Sim",R9<>"Sim"),"Sim","Não") -> Não | AR9: 46146 | AS9: Preenchimento simulado para modelagem da página de formalização. | AT9: Base simulada ONASP/PROFOR
A10: RN-2026-009 | B10: RN | C10: Rio Grande do Norte | D10: Grupo 2 - Reforço institucional | E10: 900009/2026 | F10: 2026 | G10: Em análise do projeto | H10: Secretaria de Estado da Administração Penitenciária do Rio Grande do Norte | I10: Isabela Duarte Alves | J10: Secretário(a) estadual | K10: gabinete.rn@estado.simulado.gov.br | L10: Sérgio Dantas | M10: profor.rn@estado.simulado.gov.br | N10: 200000 | O10: 9000 | P10: =N10+O10 -> 209000 | Q10: Não | R10: Não se aplica | S10: Não | T10: Sim | U10: Sim | V10: Sim | W10: Não | X10: Não | Y10: Sim | Z10: Sim | AA10: Sim | AB10: Não | AC10: Não | AD10: Não | AE10: Não | AF10: Não | AG10: Não | AH10: Não | AI10: Não | AJ10: Não | AK10: Não | AL10: =SUM(Plano_RN!$K:$K) -> 209000 | AM10: =IF(ABS(AL10-P10)<0.01,"Não","Sim") -> Não | AN10: =COUNTIF(T10:X10,"Sim")/5 -> 0.6 | AO10: =COUNTIF(Y10:AK10,"Sim")/13 -> 0.23076923 | AP10: =(COUNTIF(T10:X10,"Sim")+COUNTIF(Y10:AK10,"Sim"))/18 -> 0.33333333 | AQ10: =IF(AND(Q10="Sim",R10<>"Sim"),"Sim","Não") -> Não | AR10: 46146 | AS10: Preenchimento simulado para modelagem da página de formalização. | AT10: Base simulada ONASP/PROFOR
A11: RS-2026-010 | B11: RS | C11: Rio Grande do Sul | D11: Grupo 1 - Condição suspensiva | E11: 900010/2026 | F11: 2026 | G11: Apta à formalização | H11: Secretaria de Sistemas Penal e Socioeducativo do Rio Grande do Sul | I11: João Ricardo Weber | J11: Secretário(a) estadual | K11: gabinete.rs@estado.simulado.gov.br | L11: Patrícia Müller | M11: profor.rs@estado.simulado.gov.br | N11: 200000 | O11: 18000 | P11: =N11+O11 -> 218000 | Q11: Sim | R11: Sim | S11: Sim | T11: Sim | U11: Sim | V11: Sim | W11: Sim | X11: Sim | Y11: Sim | Z11: Sim | AA11: Sim | AB11: Sim | AC11: Sim | AD11: Sim | AE11: Sim | AF11: Sim | AG11: Não | AH11: Não | AI11: Não | AJ11: Não | AK11: Não | AL11: =SUM(Plano_RS!$K:$K) -> 218000 | AM11: =IF(ABS(AL11-P11)<0.01,"Não","Sim") -> Não | AN11: =COUNTIF(T11:X11,"Sim")/5 -> 1 | AO11: =COUNTIF(Y11:AK11,"Sim")/13 -> 0.61538462 | AP11: =(COUNTIF(T11:X11,"Sim")+COUNTIF(Y11:AK11,"Sim"))/18 -> 0.72222222 | AQ11: =IF(AND(Q11="Sim",R11<>"Sim"),"Sim","Não") -> Não | AR11: 46146 | AS11: Preenchimento simulado para modelagem da página de formalização. | AT11: Base simulada ONASP/PROFOR
A12: SE-2026-011 | B12: SE | C12: Sergipe | D12: Grupo 1 - Condição suspensiva | E12: 900011/2026 | F12: 2026 | G12: Formalização pendente | H12: Secretaria de Estado da Justiça e de Defesa do Consumidor de Sergipe | I12: Larissa Barreto Santos | J12: Secretário(a) estadual | K12: gabinete.se@estado.simulado.gov.br | L12: Tiago Melo | M12: profor.se@estado.simulado.gov.br | N12: 200000 | O12: 7000 | P12: =N12+O12 -> 207000 | Q12: Sim | R12: Não | S12: Sim | T12: Sim | U12: Sim | V12: Sim | W12: Sim | X12: Não | Y12: Sim | Z12: Sim | AA12: Sim | AB12: Sim | AC12: Sim | AD12: Sim | AE12: Sim | AF12: Não | AG12: Não | AH12: Não | AI12: Não | AJ12: Não | AK12: Não | AL12: =SUM(Plano_SE!$K:$K) -> 207000 | AM12: =IF(ABS(AL12-P12)<0.01,"Não","Sim") -> Não | AN12: =COUNTIF(T12:X12,"Sim")/5 -> 0.8 | AO12: =COUNTIF(Y12:AK12,"Sim")/13 -> 0.53846154 | AP12: =(COUNTIF(T12:X12,"Sim")+COUNTIF(Y12:AK12,"Sim"))/18 -> 0.61111111 | AQ12: =IF(AND(Q12="Sim",R12<>"Sim"),"Sim","Não") -> Sim | AR12: 46146 | AS12: Preenchimento simulado para modelagem da página de formalização. | AT12: Base simulada ONASP/PROFOR
A13: RR-2026-012 | B13: RR | C13: Roraima | D13: Grupo 1 - Condição suspensiva | E13: 900012/2026 | F13: 2026 | G13: Em análise técnica | H13: Secretaria de Estado da Justiça e da Cidadania de Roraima | I13: Marcos Vinícius Mota | J13: Secretário(a) estadual | K13: gabinete.rr@estado.simulado.gov.br | L13: Bianca Araújo | M13: profor.rr@estado.simulado.gov.br | N13: 200000 | O13: 6000 | P13: =N13+O13 -> 206000 | Q13: Sim | R13: Não | S13: Não | T13: Sim | U13: Sim | V13: Sim | W13: Não | X13: Não | Y13: Sim | Z13: Sim | AA13: Sim | AB13: Não | AC13: Não | AD13: Não | AE13: Não | AF13: Não | AG13: Não | AH13: Não | AI13: Não | AJ13: Não | AK13: Não | AL13: =SUM(Plano_RR!$K:$K) -> 206000 | AM13: =IF(ABS(AL13-P13)<0.01,"Não","Sim") -> Não | AN13: =COUNTIF(T13:X13,"Sim")/5 -> 0.6 | AO13: =COUNTIF(Y13:AK13,"Sim")/13 -> 0.23076923 | AP13: =(COUNTIF(T13:X13,"Sim")+COUNTIF(Y13:AK13,"Sim"))/18 -> 0.33333333 | AQ13: =IF(AND(Q13="Sim",R13<>"Sim"),"Sim","Não") -> Sim | AR13: 46146 | AS13: Preenchimento simulado para modelagem da página de formalização. | AT13: Base simulada ONASP/PROFOR
A14: GO-2026-013 | B14: GO | C14: Goiás | D14: Grupo 2 - Reforço institucional | E14: 900013/2026 | F14: 2026 | G14: Apta à celebração | H14: Diretoria-Geral de Polícia Penal de Goiás | I14: Natália Guimarães Prado | J14: Secretário(a) estadual | K14: gabinete.go@estado.simulado.gov.br | L14: Felipe Batista | M14: profor.go@estado.simulado.gov.br | N14: 200000 | O14: 16000 | P14: =N14+O14 -> 216000 | Q14: Não | R14: Não se aplica | S14: Sim | T14: Sim | U14: Sim | V14: Sim | W14: Sim | X14: Sim | Y14: Sim | Z14: Sim | AA14: Sim | AB14: Sim | AC14: Sim | AD14: Sim | AE14: Sim | AF14: Sim | AG14: Sim | AH14: Sim | AI14: Sim | AJ14: Sim | AK14: Não | AL14: =SUM(Plano_GO!$K:$K) -> 216000 | AM14: =IF(ABS(AL14-P14)<0.01,"Não","Sim") -> Não | AN14: =COUNTIF(T14:X14,"Sim")/5 -> 1 | AO14: =COUNTIF(Y14:AK14,"Sim")/13 -> 0.92307692 | AP14: =(COUNTIF(T14:X14,"Sim")+COUNTIF(Y14:AK14,"Sim"))/18 -> 0.94444444 | AQ14: =IF(AND(Q14="Sim",R14<>"Sim"),"Sim","Não") -> Não | AR14: 46146 | AS14: Preenchimento simulado para modelagem da página de formalização. | AT14: Base simulada ONASP/PROFOR
A15: AM-2026-014 | B15: AM | C15: Amazonas | D15: Grupo 2 - Reforço institucional | E15: 900014/2026 | F15: 2026 | G15: Projeto aprovado | H15: Secretaria de Estado de Administração Penitenciária do Amazonas | I15: Otávio Henrique Barros | J15: Secretário(a) estadual | K15: gabinete.am@estado.simulado.gov.br | L15: Márcia Oliveira | M15: profor.am@estado.simulado.gov.br | N15: 200000 | O15: 11000 | P15: =N15+O15 -> 211000 | Q15: Não | R15: Não se aplica | S15: Sim | T15: Sim | U15: Sim | V15: Sim | W15: Sim | X15: Sim | Y15: Sim | Z15: Sim | AA15: Sim | AB15: Sim | AC15: Sim | AD15: Sim | AE15: Sim | AF15: Sim | AG15: Não | AH15: Não | AI15: Não | AJ15: Não | AK15: Não | AL15: =SUM(Plano_AM!$K:$K) -> 211000 | AM15: =IF(ABS(AL15-P15)<0.01,"Não","Sim") -> Não | AN15: =COUNTIF(T15:X15,"Sim")/5 -> 1 | AO15: =COUNTIF(Y15:AK15,"Sim")/13 -> 0.61538462 | AP15: =(COUNTIF(T15:X15,"Sim")+COUNTIF(Y15:AK15,"Sim"))/18 -> 0.72222222 | AQ15: =IF(AND(Q15="Sim",R15<>"Sim"),"Sim","Não") -> Não | AR15: 46146 | AS15: Preenchimento simulado para modelagem da página de formalização. | AT15: Base simulada ONASP/PROFOR

Sheet Checklist_Documentos
A1: ID_Checklist | B1: ID_Proposta | C1: UF | D1: Etapa | E1: Código Documento | F1: Nome Documento | G1: Obrigatório? | H1: Enviado? | I1: Data Envio | J1: Status Análise | K1: Unidade Responsável | L1: Link SEI/Transferegov | M1: Pendência | N1: Data Validação | O1: Observação
A2: AP-2026-001-DOC_PROJ_01 | B2: AP-2026-001 | C2: AP | D2: Projeto | E2: DOC_PROJ_01 | F2: Plano de Trabalho | G2: Sim | H2: Sim | I2: 46133 | J2: Validado | K2: ONASP | L2: SEI_SIMULADO/AP-2026-001/DOC_PROJ_01 | N2: 46146 | O2: Linha simulada para teste de trilha de formalização.
A3: AP-2026-001-DOC_PROJ_02 | B3: AP-2026-001 | C3: AP | D3: Projeto | E3: DOC_PROJ_02 | F3: Cronograma físico | G3: Sim | H3: Sim | I3: 46133 | J3: Validado | K3: ONASP | L3: SEI_SIMULADO/AP-2026-001/DOC_PROJ_02 | N3: 46146 | O3: Linha simulada para teste de trilha de formalização.
A4: AP-2026-001-DOC_PROJ_03 | B4: AP-2026-001 | C4: AP | D4: Projeto | E4: DOC_PROJ_03 | F4: Plano de aplicação detalhado | G4: Sim | H4: Sim | I4: 46133 | J4: Validado | K4: ONASP | L4: SEI_SIMULADO/AP-2026-001/DOC_PROJ_03 | N4: 46146 | O4: Linha simulada para teste de trilha de formalização.
A5: AP-2026-001-DOC_PROJ_04 | B5: AP-2026-001 | C5: AP | D5: Projeto | E5: DOC_PROJ_04 | F5: Declaração de compatibilidade do objeto | G5: Sim | H5: Sim | I5: 46133 | J5: Validado | K5: ONASP | L5: SEI_SIMULADO/AP-2026-001/DOC_PROJ_04 | N5: 46146 | O5: Linha simulada para teste de trilha de formalização.
A6: AP-2026-001-DOC_PROJ_05 | B6: AP-2026-001 | C6: AP | D6: Projeto | E6: DOC_PROJ_05 | F6: Descrição da unidade beneficiária | G6: Sim | H6: Sim | I6: 46133 | J6: Validado | K6: ONASP | L6: SEI_SIMULADO/AP-2026-001/DOC_PROJ_05 | N6: 46146 | O6: Linha simulada para teste de trilha de formalização.
A7: AP-2026-001-DOC_FORM_01 | B7: AP-2026-001 | C7: AP | D7: Formalização | E7: DOC_FORM_01 | F7: Comprovação de representação legal | G7: Sim | H7: Sim | I7: 46133 | J7: Validado | K7: CGGIR | L7: SEI_SIMULADO/AP-2026-001/DOC_FORM_01 | N7: 46146 | O7: Linha simulada para teste de trilha de formalização.
A8: AP-2026-001-DOC_FORM_02 | B8: AP-2026-001 | C8: AP | D8: Formalização | E8: DOC_FORM_02 | F8: Ato de posse ou nomeação do gestor | G8: Sim | H8: Sim | I8: 46133 | J8: Validado | K8: CGGIR | L8: SEI_SIMULADO/AP-2026-001/DOC_FORM_02 | N8: 46146 | O8: Linha simulada para teste de trilha de formalização.
A9: AP-2026-001-DOC_FORM_03 | B9: AP-2026-001 | C9: AP | D9: Formalização | E9: DOC_FORM_03 | F9: Declaração de contrapartida financeira | G9: Sim | H9: Sim | I9: 46133 | J9: Validado | K9: CGGIR | L9: SEI_SIMULADO/AP-2026-001/DOC_FORM_03 | N9: 46146 | O9: Linha simulada para teste de trilha de formalização.
A10: AP-2026-001-DOC_FORM_04 | B10: AP-2026-001 | C10: AP | D10: Formalização | E10: DOC_FORM_04 | F10: Declaração de capacidade técnico-operacional do convenente | G10: Sim | H10: Sim | I10: 46133 | J10: Validado | K10: CGGIR | L10: SEI_SIMULADO/AP-2026-001/DOC_FORM_04 | N10: 46146 | O10: Linha simulada para teste de trilha de formalização.
A11: AP-2026-001-DOC_FORM_05 | B11: AP-2026-001 | C11: AP | D11: Formalização | E11: DOC_FORM_05 | F11: Regularidade fiscal/cadastral aplicável | G11: Sim | H11: Sim | I11: 46133 | J11: Validado | K11: CGGIR | L11: SEI_SIMULADO/AP-2026-001/DOC_FORM_05 | N11: 46146 | O11: Linha simulada para teste de trilha de formalização.
A12: AP-2026-001-DOC_FORM_06 | B12: AP-2026-001 | C12: AP | D12: Formalização | E12: DOC_FORM_06 | F12: Cadastro atualizado no Transferegov.br | G12: Sim | H12: Sim | I12: 46133 | J12: Validado | K12: CGGIR | L12: SEI_SIMULADO/AP-2026-001/DOC_FORM_06 | N12: 46146 | O12: Linha simulada para teste de trilha de formalização.
A13: AP-2026-001-DOC_FORM_07 | B13: AP-2026-001 | C13: AP | D13: Formalização | E13: DOC_FORM_07 | F13: Declaração de inexistência de impedimentos | G13: Sim | H13: Sim | I13: 46133 | J13: Validado | K13: CGGIR | L13: SEI_SIMULADO/AP-2026-001/DOC_FORM_07 | N13: 46146 | O13: Linha simulada para teste de trilha de formalização.
... A16: AP-2026-001-DOC_FORM_10 | B16: AP-2026-001 | C16: AP | D16: Formalização | E16: DOC_FORM_10 | F16: Indicação da conta específica | G16: Sim | H16: Sim | I16: 46133 | J16: Validado | K16: CGGIR | L16: SEI_SIMULADO/AP-2026-001/DOC_FORM_10 | N16: 46146 | O16: Linha simulada para teste de trilha de formalização.
A17: AP-2026-001-DOC_FORM_11 | B17: AP-2026-001 | C17: AP | D17: Formalização | E17: DOC_FORM_11 | F17: Minuta/termo de convênio validado | G17: Sim | H17: Não | J17: Não enviado | K17: CGGIR | M17: Aguardando envio pelo convenente. | O17: Linha simulada para teste de trilha de formalização.
A18: AP-2026-001-DOC_FORM_12 | B18: AP-2026-001 | C18: AP | D18: Formalização | E18: DOC_FORM_12 | F18: Manifestação jurídica ou documento equivalente do ente | G18: Sim | H18: Não | J18: Não enviado | K18: CGGIR | M18: Aguardando envio pelo convenente. | O18: Linha simulada para teste de trilha de formalização.
A19: AP-2026-001-DOC_FORM_13 | B19: AP-2026-001 | C19: AP | D19: Formalização | E19: DOC_FORM_13 | F19: Autorização/anuência da autoridade competente | G19: Sim | H19: Não | J19: Não enviado | K19: CGGIR | M19: Aguardando envio pelo convenente. | O19: Linha simulada para teste de trilha de formalização.
A20: BA-2026-002-DOC_PROJ_01 | B20: BA-2026-002 | C20: BA | D20: Projeto | E20: DOC_PROJ_01 | F20: Plano de Trabalho | G20: Sim | H20: Sim | I20: 46134 | J20: Validado | K20: ONASP | L20: SEI_SIMULADO/BA-2026-002/DOC_PROJ_01 | N20: 46146 | O20: Linha simulada para teste de trilha de formalização.
A21: BA-2026-002-DOC_PROJ_02 | B21: BA-2026-002 | C21: BA | D21: Projeto | E21: DOC_PROJ_02 | F21: Cronograma físico | G21: Sim | H21: Sim | I21: 46134 | J21: Validado | K21: ONASP | L21: SEI_SIMULADO/BA-2026-002/DOC_PROJ_02 | N21: 46146 | O21: Linha simulada para teste de trilha de formalização.
A22: BA-2026-002-DOC_PROJ_03 | B22: BA-2026-002 | C22: BA | D22: Projeto | E22: DOC_PROJ_03 | F22: Plano de aplicação detalhado | G22: Sim | H22: Sim | I22: 46134 | J22: Em análise | K22: ONASP | L22: SEI_SIMULADO/BA-2026-002/DOC_PROJ_03 | O22: Linha simulada para teste de trilha de formalização.
A23: BA-2026-002-DOC_PROJ_04 | B23: BA-2026-002 | C23: BA | D23: Projeto | E23: DOC_PROJ_04 | F23: Declaração de compatibilidade do objeto | G23: Sim | H23: Sim | I23: 46134 | J23: Validado | K23: ONASP | L23: SEI_SIMULADO/BA-2026-002/DOC_PROJ_04 | N23: 46146 | O23: Linha simulada para teste de trilha de formalização.
A24: BA-2026-002-DOC_PROJ_05 | B24: BA-2026-002 | C24: BA | D24: Projeto | E24: DOC_PROJ_05 | F24: Descrição da unidade beneficiária | G24: Sim | H24: Sim | I24: 46134 | J24: Validado | K24: ONASP | L24: SEI_SIMULADO/BA-2026-002/DOC_PROJ_05 | N24: 46146 | O24: Linha simulada para teste de trilha de formalização.
A25: BA-2026-002-DOC_FORM_01 | B25: BA-2026-002 | C25: BA | D25: Formalização | E25: DOC_FORM_01 | F25: Comprovação de representação legal | G25: Sim | H25: Sim | I25: 46134 | J25: Em análise | K25: CGGIR | L25: SEI_SIMULADO/BA-2026-002/DOC_FORM_01 | O25: Linha simulada para teste de trilha de formalização.
A26: BA-2026-002-DOC_FORM_02 | B26: BA-2026-002 | C26: BA | D26: Formalização | E26: DOC_FORM_02 | F26: Ato de posse ou nomeação do gestor | G26: Sim | H26: Sim | I26: 46134 | J26: Validado | K26: CGGIR | L26: SEI_SIMULADO/BA-2026-002/DOC_FORM_02 | N26: 46146 | O26: Linha simulada para teste de trilha de formalização.
A27: BA-2026-002-DOC_FORM_03 | B27: BA-2026-002 | C27: BA | D27: Formalização | E27: DOC_FORM_03 | F27: Declaração de contrapartida financeira | G27: Sim | H27: Sim | I27: 46134 | J27: Validado | K27: CGGIR | L27: SEI_SIMULADO/BA-2026-002/DOC_FORM_03 | N27: 46146 | O27: Linha simulada para teste de trilha de formalização.
A28: BA-2026-002-DOC_FORM_04 | B28: BA-2026-002 | C28: BA | D28: Formalização | E28: DOC_FORM_04 | F28: Declaração de capacidade técnico-operacional do convenente | G28: Sim | H28: Sim | I28: 46134 | J28: Em análise | K28: CGGIR | L28: SEI_SIMULADO/BA-2026-002/DOC_FORM_04 | O28: Linha simulada para teste de trilha de formalização.
A29: BA-2026-002-DOC_FORM_05 | B29: BA-2026-002 | C29: BA | D29: Formalização | E29: DOC_FORM_05 | F29: Regularidade fiscal/cadastral aplicável | G29: Sim | H29: Sim | I29: 46134 | J29: Validado | K29: CGGIR | L29: SEI_SIMULADO/BA-2026-002/DOC_FORM_05 | N29: 46146 | O29: Linha simulada para teste de trilha de formalização.
A30: BA-2026-002-DOC_FORM_06 | B30: BA-2026-002 | C30: BA | D30: Formalização | E30: DOC_FORM_06 | F30: Cadastro atualizado no Transferegov.br | G30: Sim | H30: Sim | I30: 46134 | J30: Validado | K30: CGGIR | L30: SEI_SIMULADO/BA-2026-002/DOC_FORM_06 | N30: 46146 | O30: Linha simulada para teste de trilha de formalização.
A31: BA-2026-002-DOC_FORM_07 | B31: BA-2026-002 | C31: BA | D31: Formalização | E31: DOC_FORM_07 | F31: Declaração de inexistência de impedimentos | G31: Sim | H31: Sim | I31: 46134 | J31: Em análise | K31: CGGIR | L31: SEI_SIMULADO/BA-2026-002/DOC_FORM_07 | O31: Linha simulada para teste de trilha de formalização.
A32: BA-2026-002-DOC_FORM_08 | B32: BA-2026-002 | C32: BA | D32: Formalização | E32: DOC_FORM_08 | F32: Plano de sustentabilidade dos bens | G32: Sim | H32: Sim | I32: 46134 | J32: Validado | K32: CGGIR | L32: SEI_SIMULADO/BA-2026-002/DOC_FORM_08 | N32: 46146 | O32: Linha simulada para teste de trilha de formalização.
A33: BA-2026-002-DOC_FORM_09 | B33: BA-2026-002 | C33: BA | D33: Formalização | E33: DOC_FORM_09 | F33: Declaração de ciência das regras de execução | G33: Sim | H33: Não | J33: Não enviado | K33: CGGIR | M33: Aguardando envio pelo convenente. | O33: Linha simulada para teste de trilha de formalização.
A34: BA-2026-002-DOC_FORM_10 | B34: BA-2026-002 | C34: BA | D34: Formalização | E34: DOC_FORM_10 | F34: Indicação da conta específica | G34: Sim | H34: Não | J34: Não enviado | K34: CGGIR | M34: Aguardando envio pelo convenente. | O34: Linha simulada para teste de trilha de formalização.
A35: BA-2026-002-DOC_FORM_11 | B35: BA-2026-002 | C35: BA | D35: Formalização | E35: DOC_FORM_11 | F35: Minuta/termo de convênio validado | G35: Sim | H35: Não | J35: Não enviado | K35: CGGIR | M35: Aguardando envio pelo convenente. | O35: Linha simulada para teste de trilha de formalização.
A36: BA-2026-002-DOC_FORM_12 | B36: BA-2026-002 | C36: BA | D36: Formalização | E36: DOC_FORM_12 | F36: Manifestação jurídica ou documento equivalente do ente | G36: Sim | H36: Não | J36: Não enviado | K36: CGGIR | M36: Aguardando envio pelo convenente. | O36: Linha simulada para teste de trilha de formalização.
A37: BA-2026-002-DOC_FORM_13 | B37: BA-2026-002 | C37: BA | D37: Formalização | E37: DOC_FORM_13 | F37: Autorização/anuência da autoridade competente | G37: Sim | H37: Não | J37: Não enviado | K37: CGGIR | M37: Aguardando envio pelo convenente. | O37: Linha simulada para teste de trilha de formalização.
A38: CE-2026-003-DOC_PROJ_01 | B38: CE-2026-003 | C38: CE | D38: Projeto | E38: DOC_PROJ_01 | F38: Plano de Trabalho | G38: Sim | H38: Sim | I38: 46135 | J38: Validado | K38: ONASP | L38: SEI_SIMULADO/CE-2026-003/DOC_PROJ_01 | N38: 46146 | O38: Linha simulada para teste de trilha de formalização.
A39: CE-2026-003-DOC_PROJ_02 | B39: CE-2026-003 | C39: CE | D39: Projeto | E39: DOC_PROJ_02 | F39: Cronograma físico | G39: Sim | H39: Sim | I39: 46135 | J39: Validado | K39: ONASP | L39: SEI_SIMULADO/CE-2026-003/DOC_PROJ_02 | N39: 46146 | O39: Linha simulada para teste de trilha de formalização.
A40: CE-2026-003-DOC_PROJ_03 | B40: CE-2026-003 | C40: CE | D40: Projeto | E40: DOC_PROJ_03 | F40: Plano de aplicação detalhado | G40: Sim | H40: Sim | I40: 46135 | J40: Validado | K40: ONASP | L40: SEI_SIMULADO/CE-2026-003/DOC_PROJ_03 | N40: 46146 | O40: Linha simulada para teste de trilha de formalização.
A41: CE-2026-003-DOC_PROJ_04 | B41: CE-2026-003 | C41: CE | D41: Projeto | E41: DOC_PROJ_04 | F41: Declaração de compatibilidade do objeto | G41: Sim | H41: Sim | I41: 46135 | J41: Pendente de correção | K41: ONASP | L41: SEI_SIMULADO/CE-2026-003/DOC_PROJ_04 | M41: Revisar consistência das informações e reenviar versão ajustada. | O41: Linha simulada para teste de trilha de formalização.
A42: CE-2026-003-DOC_PROJ_05 | B42: CE-2026-003 | C42: CE | D42: Projeto | E42: DOC_PROJ_05 | F42: Descrição da unidade beneficiária | G42: Sim | H42: Não | J42: Não enviado | K42: ONASP | M42: Aguardando envio pelo convenente. | O42: Linha simulada para teste de trilha de formalização.
...

Sheet Dicionario_Documentos
A1: Código | B1: Etapa | C1: Nome do Documento | D1: Obrigatório? | E1: Aplicável a quais UFs | F1: Observação
A2: DOC_PROJ_01 | B2: Projeto | C2: Plano de Trabalho | D2: Sim | E2: Todas | F2: Documento estruturante da proposta.
A3: DOC_PROJ_02 | B3: Projeto | C3: Cronograma físico | D3: Sim | E3: Todas | F3: Deve prever adesão/integração/indicação da Plataforma Fala.BR.
A4: DOC_PROJ_03 | B4: Projeto | C4: Plano de aplicação detalhado | D4: Sim | E4: Todas | F4: Itens, quantidades, valores unitários e totais.
A5: DOC_PROJ_04 | B5: Projeto | C5: Declaração de compatibilidade do objeto | D5: Sim | E5: Todas | F5: Compatibilidade com aparelhamento da ouvidoria; exclui obras e reformas.
A6: DOC_PROJ_05 | B6: Projeto | C6: Descrição da unidade beneficiária | D6: Sim | E6: Todas | F6: Identificação da ouvidoria de serviços penais beneficiária.
A7: DOC_FORM_01 | B7: Formalização | C7: Comprovação de representação legal | D7: Sim | E7: Todas | F7: Documento de suporte à formalização do instrumento.
A8: DOC_FORM_02 | B8: Formalização | C8: Ato de posse ou nomeação do gestor | D8: Sim | E8: Todas | F8: Documento de suporte à formalização do instrumento.
A9: DOC_FORM_03 | B9: Formalização | C9: Declaração de contrapartida financeira | D9: Sim | E9: Todas | F9: Documento de suporte à formalização do instrumento.
A10: DOC_FORM_04 | B10: Formalização | C10: Declaração de capacidade técnico-operacional do convenente | D10: Sim | E10: Todas | F10: Documento de suporte à formalização do instrumento.
A11: DOC_FORM_05 | B11: Formalização | C11: Regularidade fiscal/cadastral aplicável | D11: Sim | E11: Todas | F11: Documento de suporte à formalização do instrumento.
A12: DOC_FORM_06 | B12: Formalização | C12: Cadastro atualizado no Transferegov.br | D12: Sim | E12: Todas | F12: Documento de suporte à formalização do instrumento.
... A20: DOC_COND_01 | B20: Condição suspensiva | C20: Ato normativo publicado que institui ouvidoria própria de serviços penais | D20: Sim | E20: PA, RR, RS e SE | F20: Condição suspensiva do PROFOR/ONASP para UFs do Grupo 1.

Sheet Gestores_Responsaveis
A1: UF | B1: Órgão estadual | C1: Tipo responsável | D1: Nome | E1: Cargo | F1: E-mail | G1: Telefone | H1: Início vigência | I1: Fim vigência | J1: Ativo?
A2: AP | B2: Secretaria de Administração Penitenciária do Amapá | C2: Gestor político | D2: Ana Paula Monteiro | E2: Secretário(a) estadual | F2: gabinete.ap@estado.simulado.gov.br | G2: (61) 3001-0000 | H2: 46023 | J2: Sim
A3: AP | B3: Secretaria de Administração Penitenciária do Amapá | C3: Responsável técnico | D3: Rafael Lima | E3: Coordenador(a) da proposta | F3: profor.ap@estado.simulado.gov.br | G3: (61) 3001-1000 | H3: 46023 | J3: Sim
A4: BA | B4: Secretaria de Administração Penitenciária e Ressocialização da Bahia | C4: Gestor político | D4: Bruno Reis Almeida | E4: Secretário(a) estadual | F4: gabinete.ba@estado.simulado.gov.br | G4: (61) 3002-0000 | H4: 46023 | J4: Sim
A5: BA | B5: Secretaria de Administração Penitenciária e Ressocialização da Bahia | C5: Responsável técnico | D5: Mariana Torres | E5: Coordenador(a) da proposta | F5: profor.ba@estado.simulado.gov.br | G5: (61) 3002-1000 | H5: 46023 | J5: Sim
A6: CE | B6: Secretaria da Administração Penitenciária e Ressocialização do Ceará | C6: Gestor político | D6: Camila Nogueira Lima | E6: Secretário(a) estadual | F6: gabinete.ce@estado.simulado.gov.br | G6: (61) 3003-0000 | H6: 46023 | J6: Sim
A7: CE | B7: Secretaria da Administração Penitenciária e Ressocialização do Ceará | C7: Responsável técnico | D7: Paulo César | E7: Coordenador(a) da proposta | F7: profor.ce@estado.simulado.gov.br | G7: (61) 3003-1000 | H7: 46023 | J7: Sim
A8: DF | B8: Secretaria de Estado de Administração Penitenciária do Distrito Federal | C8: Gestor político | D8: Daniel Freitas Rocha | E8: Secretário(a) estadual | F8: gabinete.df@estado.simulado.gov.br | G8: (61) 3004-0000 | H8: 46023 | J8: Sim
A9: DF | B9: Secretaria de Estado de Administração Penitenciária do Distrito Federal | C9: Responsável técnico | D9: Lúcia Amaral | E9: Coordenador(a) da proposta | F9: profor.df@estado.simulado.gov.br | G9: (61) 3004-1000 | H9: 46023 | J9: Sim
A10: ES | B10: Secretaria de Estado da Justiça do Espírito Santo | C10: Gestor político | D10: Eduarda Siqueira Martins | E10: Secretário(a) estadual | F10: gabinete.es@estado.simulado.gov.br | G10: (61) 3005-0000 | H10: 46023 | J10: Sim
A11: ES | B11: Secretaria de Estado da Justiça do Espírito Santo | C11: Responsável técnico | D11: Renato Peixoto | E11: Coordenador(a) da proposta | F11: profor.es@estado.simulado.gov.br | G11: (61) 3005-1000 | H11: 46023 | J11: Sim
A12: MG | B12: Secretaria de Estado de Justiça e Segurança Pública de Minas Gerais | C12: Gestor político | D12: Fernando Costa Andrade | E12: Secretário(a) estadual | F12: gabinete.mg@estado.simulado.gov.br | G12: (61) 3006-0000 | H12: 46023 | J12: Sim
A13: MG | B13: Secretaria de Estado de Justiça e Segurança Pública de Minas Gerais | C13: Responsável técnico | D13: Aline Campos | E13: Coordenador(a) da proposta | F13: profor.mg@estado.simulado.gov.br | G13: (61) 3006-1000 | H13: 46023 | J13: Sim
... A29: AM | B29: Secretaria de Estado de Administração Penitenciária do Amazonas | C29: Responsável técnico | D29: Márcia Oliveira | E29: Coordenador(a) da proposta | F29: profor.am@estado.simulado.gov.br | G29: (61) 3014-1000 | H29: 46023 | J29: Sim

Sheet Parametros
A1: Tipo | B1: Valor
A2: Status Geral | B2: Não iniciada
A3: Status Geral | B3: Proposta em elaboração
A4: Status Geral | B4: Proposta cadastrada
A5: Status Geral | B5: Em análise do projeto
A6: Status Geral | B6: Em análise técnica
A7: Status Geral | B7: Em complementação pelo Estado
A8: Status Geral | B8: Projeto aprovado
A9: Status Geral | B9: Em análise de formalização
A10: Status Geral | B10: Formalização pendente
A11: Status Geral | B11: Apta à formalização
A12: Status Geral | B12: Apta à celebração
... A29: Fonte | B29: Contrapartida

Sheet Validacoes
A1: UF | B1: ID_Proposta | C1: Valor Global | D1: Soma Plano | E1: Plano fecha? | F1: Repasse = R$ 200.000? | G1: Fala.BR previsto? | H1: Condição suspensiva pendente? | I1: Documentos projeto completos? | J1: Documentos formalização completos? | K1: Status de alerta
A2: =Painel_Propostas!B2 -> AP | B2: =Painel_Propostas!A2 -> AP-2026-001 | C2: =Painel_Propostas!P2 -> 212000 | D2: =Painel_Propostas!AL2 -> 212000 | E2: =IF(ABS(D2-C2)<0.01,"Sim","Não") -> Sim | F2: =IF(Painel_Propostas!N2=200000,"Sim","Não") -> Sim | G2: =Painel_Propostas!S2 -> Sim | H2: =Painel_Propostas!AQ2 -> Não | I2: =IF(Painel_Propostas!AN2=1,"Sim","Não") -> Sim | J2: =IF(Painel_Propostas!AO2=1,"Sim","Não") -> Não | K2: =IF(OR(E2<>"Sim",F2<>"Sim",G2<>"Sim",H2="Sim"),"Atenção","OK") -> OK
A3: =Painel_Propostas!B3 -> BA | B3: =Painel_Propostas!A3 -> BA-2026-002 | C3: =Painel_Propostas!P3 -> 215000 | D3: =Painel_Propostas!AL3 -> 215000 | E3: =IF(ABS(D3-C3)<0.01,"Sim","Não") -> Sim | F3: =IF(Painel_Propostas!N3=200000,"Sim","Não") -> Sim | G3: =Painel_Propostas!S3 -> Sim | H3: =Painel_Propostas!AQ3 -> Não | I3: =IF(Painel_Propostas!AN3=1,"Sim","Não") -> Sim | J3: =IF(Painel_Propostas!AO3=1,"Sim","Não") -> Não | K3: =IF(OR(E3<>"Sim",F3<>"Sim",G3<>"Sim",H3="Sim"),"Atenção","OK") -> OK
A4: =Painel_Propostas!B4 -> CE | B4: =Painel_Propostas!A4 -> CE-2026-003 | C4: =Painel_Propostas!P4 -> 210000 | D4: =Painel_Propostas!AL4 -> 210000 | E4: =IF(ABS(D4-C4)<0.01,"Sim","Não") -> Sim | F4: =IF(Painel_Propostas!N4=200000,"Sim","Não") -> Sim | G4: =Painel_Propostas!S4 -> Sim | H4: =Painel_Propostas!AQ4 -> Não | I4: =IF(Painel_Propostas!AN4=1,"Sim","Não") -> Não | J4: =IF(Painel_Propostas!AO4=1,"Sim","Não") -> Não | K4: =IF(OR(E4<>"Sim",F4<>"Sim",G4<>"Sim",H4="Sim"),"Atenção","OK") -> OK
A5: =Painel_Propostas!B5 -> DF | B5: =Painel_Propostas!A5 -> DF-2026-004 | C5: =Painel_Propostas!P5 -> 225000 | D5: =Painel_Propostas!AL5 -> 225000 | E5: =IF(ABS(D5-C5)<0.01,"Sim","Não") -> Sim | F5: =IF(Painel_Propostas!N5=200000,"Sim","Não") -> Sim | G5: =Painel_Propostas!S5 -> Sim | H5: =Painel_Propostas!AQ5 -> Não | I5: =IF(Painel_Propostas!AN5=1,"Sim","Não") -> Sim | J5: =IF(Painel_Propostas!AO5=1,"Sim","Não") -> Sim | K5: =IF(OR(E5<>"Sim",F5<>"Sim",G5<>"Sim",H5="Sim"),"Atenção","OK") -> OK
A6: =Painel_Propostas!B6 -> ES | B6: =Painel_Propostas!A6 -> ES-2026-005 | C6: =Painel_Propostas!P6 -> 210000 | D6: =Painel_Propostas!AL6 -> 210000 | E6: =IF(ABS(D6-C6)<0.01,"Sim","Não") -> Sim | F6: =IF(Painel_Propostas!N6=200000,"Sim","Não") -> Sim | G6: =Painel_Propostas!S6 -> Não | H6: =Painel_Propostas!AQ6 -> Não | I6: =IF(Painel_Propostas!AN6=1,"Sim","Não") -> Não | J6: =IF(Painel_Propostas!AO6=1,"Sim","Não") -> Não | K6: =IF(OR(E6<>"Sim",F6<>"Sim",G6<>"Sim",H6="Sim"),"Atenção","OK") -> Atenção
A7: =Painel_Propostas!B7 -> MG | B7: =Painel_Propostas!A7 -> MG-2026-006 | C7: =Painel_Propostas!P7 -> 230000 | D7: =Painel_Propostas!AL7 -> 230000 | E7: =IF(ABS(D7-C7)<0.01,"Sim","Não") -> Sim | F7: =IF(Painel_Propostas!N7=200000,"Sim","Não") -> Sim | G7: =Painel_Propostas!S7 -> Sim | H7: =Painel_Propostas!AQ7 -> Não | I7: =IF(Painel_Propostas!AN7=1,"Sim","Não") -> Não | J7: =IF(Painel_Propostas!AO7=1,"Sim","Não") -> Não | K7: =IF(OR(E7<>"Sim",F7<>"Sim",G7<>"Sim",H7="Sim"),"Atenção","OK") -> OK
A8: =Painel_Propostas!B8 -> PA | B8: =Painel_Propostas!A8 -> PA-2026-007 | C8: =Painel_Propostas!P8 -> 208000 | D8: =Painel_Propostas!AL8 -> 208000 | E8: =IF(ABS(D8-C8)<0.01,"Sim","Não") -> Sim | F8: =IF(Painel_Propostas!N8=200000,"Sim","Não") -> Sim | G8: =Painel_Propostas!S8 -> Sim | H8: =Painel_Propostas!AQ8 -> Sim | I8: =IF(Painel_Propostas!AN8=1,"Sim","Não") -> Não | J8: =IF(Painel_Propostas!AO8=1,"Sim","Não") -> Não | K8: =IF(OR(E8<>"Sim",F8<>"Sim",G8<>"Sim",H8="Sim"),"Atenção","OK") -> Atenção
A9: =Painel_Propostas!B9 -> PE | B9: =Painel_Propostas!A9 -> PE-2026-008 | C9: =Painel_Propostas!P9 -> 214000 | D9: =Painel_Propostas!AL9 -> 214000 | E9: =IF(ABS(D9-C9)<0.01,"Sim","Não") -> Sim | F9: =IF(Painel_Propostas!N9=200000,"Sim","Não") -> Sim | G9: =Painel_Propostas!S9 -> Sim | H9: =Painel_Propostas!AQ9 -> Não | I9: =IF(Painel_Propostas!AN9=1,"Sim","Não") -> Sim | J9: =IF(Painel_Propostas!AO9=1,"Sim","Não") -> Não | K9: =IF(OR(E9<>"Sim",F9<>"Sim",G9<>"Sim",H9="Sim"),"Atenção","OK") -> OK
A10: =Painel_Propostas!B10 -> RN | B10: =Painel_Propostas!A10 -> RN-2026-009 | C10: =Painel_Propostas!P10 -> 209000 | D10: =Painel_Propostas!AL10 -> 209000 | E10: =IF(ABS(D10-C10)<0.01,"Sim","Não") -> Sim | F10: =IF(Painel_Propostas!N10=200000,"Sim","Não") -> Sim | G10: =Painel_Propostas!S10 -> Não | H10: =Painel_Propostas!AQ10 -> Não | I10: =IF(Painel_Propostas!AN10=1,"Sim","Não") -> Não | J10: =IF(Painel_Propostas!AO10=1,"Sim","Não") -> Não | K10: =IF(OR(E10<>"Sim",F10<>"Sim",G10<>"Sim",H10="Sim"),"Atenção","OK") -> Atenção
A11: =Painel_Propostas!B11 -> RS | B11: =Painel_Propostas!A11 -> RS-2026-010 | C11: =Painel_Propostas!P11 -> 218000 | D11: =Painel_Propostas!AL11 -> 218000 | E11: =IF(ABS(D11-C11)<0.01,"Sim","Não") -> Sim | F11: =IF(Painel_Propostas!N11=200000,"Sim","Não") -> Sim | G11: =Painel_Propostas!S11 -> Sim | H11: =Painel_Propostas!AQ11 -> Não | I11: =IF(Painel_Propostas!AN11=1,"Sim","Não") -> Sim | J11: =IF(Painel_Propostas!AO11=1,"Sim","Não") -> Não | K11: =IF(OR(E11<>"Sim",F11<>"Sim",G11<>"Sim",H11="Sim"),"Atenção","OK") -> OK
A12: =Painel_Propostas!B12 -> SE | B12: =Painel_Propostas!A12 -> SE-2026-011 | C12: =Painel_Propostas!P12 -> 207000 | D12: =Painel_Propostas!AL12 -> 207000 | E12: =IF(ABS(D12-C12)<0.01,"Sim","Não") -> Sim | F12: =IF(Painel_Propostas!N12=200000,"Sim","Não") -> Sim | G12: =Painel_Propostas!S12 -> Sim | H12: =Painel_Propostas!AQ12 -> Sim | I12: =IF(Painel_Propostas!AN12=1,"Sim","Não") -> Não | J12: =IF(Painel_Propostas!AO12=1,"Sim","Não") -> Não | K12: =IF(OR(E12<>"Sim",F12<>"Sim",G12<>"Sim",H12="Sim"),"Atenção","OK") -> Atenção
A13: =Painel_Propostas!B13 -> RR | B13: =Painel_Propostas!A13 -> RR-2026-012 | C13: =Painel_Propostas!P13 -> 206000 | D13: =Painel_Propostas!AL13 -> 206000 | E13: =IF(ABS(D13-C13)<0.01,"Sim","Não") -> Sim | F13: =IF(Painel_Propostas!N13=200000,"Sim","Não") -> Sim | G13: =Painel_Propostas!S13 -> Não | H13: =Painel_Propostas!AQ13 -> Sim | I13: =IF(Painel_Propostas!AN13=1,"Sim","Não") -> Não | J13: =IF(Painel_Propostas!AO13=1,"Sim","Não") -> Não | K13: =IF(OR(E13<>"Sim",F13<>"Sim",G13<>"Sim",H13="Sim"),"Atenção","OK") -> Atenção
... A15: =Painel_Propostas!B15 -> AM | B15: =Painel_Propostas!A15 -> AM-2026-014 | C15: =Painel_Propostas!P15 -> 211000 | D15: =Painel_Propostas!AL15 -> 211000 | E15: =IF(ABS(D15-C15)<0.01,"Sim","Não") -> Sim | F15: =IF(Painel_Propostas!N15=200000,"Sim","Não") -> Sim | G15: =Painel_Propostas!S15 -> Sim | H15: =Painel_Propostas!AQ15 -> Não | I15: =IF(Painel_Propostas!AN15=1,"Sim","Não") -> Sim | J15: =IF(Painel_Propostas!AO15=1,"Sim","Não") -> Não | K15: =IF(OR(E15<>"Sim",F15<>"Sim",G15<>"Sim",H15="Sim"),"Atenção","OK") -> OK

Sheet Referencias
A1: Tema | B1: Referência | C1: URL / Observação
A2: Processo | B2: Processo SEI nº 08016.010062/2026-18 | C2: Informação de contexto do PROFOR/ONASP
A3: Objeto | B3: Programa de Fortalecimento das Ouvidorias de Serviços Penais – PROFOR/ONASP | C3: Aparelhamento e fortalecimento de ouvidorias estaduais e distrital
A4: Portaria SENAPPEN nº 327/2024 | B4: Fluxo, atribuições e procedimentos de instrumentos da SENAPPEN | C4: https://dspace.mj.gov.br/bitstream/1/12892/2/PRT_SENAPPEN_2024_327.html
A5: Portaria Conjunta MGI/MF/CGU nº 28/2024 | B5: Regime simplificado para convênios e contratos de repasse | C5: https://www.gov.br/transferegov/pt-br/legislacao/portarias/portaria-conjunta-mgi-mf-cgu-no-28-de-21-de-maio-de-2024
A6: Portaria Conjunta MGI/MF/CGU nº 33/2023 | B6: Normas complementares para transferências de recursos da União | C6: https://www.gov.br/transferegov/pt-br/legislacao/portarias/portaria-conjunta-mgi-mf-cgu-no-33-de-30-de-agosto-de-2023
A7: Plano Nacional Pena Justa | B7: Eixo 2; indicadores 2.4.2.1.1.1 e 2.4.2.1.2.1 | C7: Referência estratégica do PROFOR/ONASP
A8: LGPD/LAI | B8: Tratamento de dados pessoais e transparência | C8: Dados simulados; substituir por dados oficiais antes de uso externo.
A9: Nota metodológica | B9: Todos os nomes, e-mails, números de proposta e valores de contrapartida são simulados. | C9: Usar apenas como estrutura-base para implantação no aplicativo.
A10: Estrutura do plano de aplicação | B10: A aba consolidada Plano_Aplicacao foi substituída por 14 abas individualizadas, uma por UF: Plano_AP, Plano_BA, Plano_CE, Plano_DF, Plano_ES, Plano_MG, Plano_PA, Plano_PE, Plano_RN, Plano_RS, Plano_SE, Plano_RR, Plano_GO e Plano_AM. | C10: A aba Painel_Propostas soma os valores de cada guia individualizada para conferência com o valor global da proposta.

Sheet Plano_AP
A1: ID_Item | B1: ID_Proposta | C1: UF | D1: Categoria | E1: Item | F1: Descrição detalhada | G1: Unidade | H1: Quantidade | I1: Valor Unitário | J1: Fonte | K1: Valor Total | L1: Natureza | M1: Elegível? | N1: Observação
A2: AP-2026-001-01 | B2: AP-2026-001 | C2: AP | D2: Equipamento tecnológico | E2: Notebooks | F2: Equipamentos para tratamento de manifestações, atendimento e relatórios. | G2: un | H2: 7 | I2: 5800 | J2: Repasse | K2: 40600 | L2: Capital | M2: Sim | N2: Preenchimento simulado; revisar especificações no plano de trabalho definitivo.
A3: AP-2026-001-02 | B3: AP-2026-001 | C3: AP | D3: Equipamento tecnológico | E3: Computadores desktop/all-in-one | F3: Estações de trabalho para equipe da ouvidoria. | G3: un | H3: 5 | I3: 5200 | J3: Repasse | K3: 26000 | L3: Capital | M3: Sim | N3: Preenchimento simulado; revisar especificações no plano de trabalho definitivo.
A4: AP-2026-001-03 | B4: AP-2026-001 | C4: AP | D4: Equipamento tecnológico | E4: Impressoras multifuncionais | F4: Impressão e digitalização de documentos administrativos. | G4: un | H4: 2 | I4: 4500 | J4: Repasse | K4: 9000 | L4: Capital | M4: Sim | N4: Preenchimento simulado; revisar especificações no plano de trabalho definitivo.
A5: AP-2026-001-04 | B5: AP-2026-001 | C5: AP | D5: Equipamento tecnológico | E5: Scanners de documentos | F5: Digitalização de documentos e correspondências físicas. | G5: un | H5: 2 | I5: 3200 | J5: Repasse | K5: 6400 | L5: Capital | M5: Sim | N5: Preenchimento simulado; revisar especificações no plano de trabalho definitivo.
A6: AP-2026-001-05 | B6: AP-2026-001 | C6: AP | D6: Equipamento tecnológico | E6: Nobreaks | F6: Proteção elétrica dos equipamentos de atendimento. | G6: un | H6: 8 | I6: 900 | J6: Repasse | K6: 7200 | L6: Capital | M6: Sim | N6: Preenchimento simulado; revisar especificações no plano de trabalho definitivo.
A7: AP-2026-001-06 | B7: AP-2026-001 | C7: AP | D7: Mobiliário | E7: Mesas e cadeiras de atendimento | F7: Mobiliário para postos de atendimento e análise. | G7: un | H7: 8 | I7: 2300 | J7: Repasse | K7: 18400 | L7: Capital | M7: Sim | N7: Preenchimento simulado; revisar especificações no plano de trabalho definitivo.
A8: AP-2026-001-07 | B8: AP-2026-001 | C8: AP | D8: Mobiliário | E8: Armários e arquivos físicos | F8: Organização de documentos e materiais da ouvidoria. | G8: un | H8: 4 | I8: 1600 | J8: Repasse | K8: 6400 | L8: Capital | M8: Sim | N8: Preenchimento simulado; revisar especificações no plano de trabalho definitivo.
A9: AP-2026-001-08 | B9: AP-2026-001 | C9: AP | D9: Equipamento tecnológico | E9: Equipamentos de sala reservada | F9: Headsets, webcams, microfones e dispositivos auxiliares para atendimento reservado. | G9: lote | H9: 1 | I9: 15800 | J9: Repasse | K9: 15800 | L9: Capital | M9: Sim | N9: Preenchimento simulado; revisar especificações no plano de trabalho definitivo.
A10: AP-2026-001-09 | B10: AP-2026-001 | C10: AP | D10: Mobiliário e aparelhamento complementar | E10: Conjunto complementar de aparelhamento da ouvidoria | F10: Mobiliário modular, sinalização interna, suporte a equipamentos e itens complementares compatíveis com o diagnóstico local, sem obras ou reformas. | G10: lote | H10: 1 | I10: 82200 | J10: Repasse/Contrapartida | K10: 82200 | L10: Capital | M10: Sim | N10: Preenchimento simulado; revisar especificações no plano de trabalho definitivo.

Sheet Plano_BA
A1: ID_Item | B1: ID_Proposta | C1: UF | D1: Categoria | E1: Item | F1: Descrição detalhada | G1: Unidade | H1: Quantidade | I1: Valor Unitário | J1: Fonte | K1: Valor Total | L1: Natureza | M1: Elegível? | N1: Observação
A2: BA-2026-002-01 | B2: BA-2026-002 | C2: BA | D2: Equipamento tecnológico | E2: Notebooks | F2: Equipamentos para tratamento de manifestações, atendimento e relatórios. | G2: un | H2: 7 | I2: 5800 | J2: Repasse | K2: 40600 | L2: Capital | M2: Sim | N2: Preenchimento simulado; revisar especificações no plano de trabalho definitivo.
A3: BA-2026-002-02 | B3: BA-2026-002 | C3: BA | D3: Equipamento tecnológico | E3: Computadores desktop/all-in-one | F3: Estações de trabalho para equipe da ouvidoria. | G3: un | H3: 5 | I3: 5200 | J3: Repasse | K3: 26000 | L3: Capital | M3: Sim | N3: Preenchimento simulado; revisar especificações no plano de trabalho definitivo.
A4: BA-2026-002-03 | B4: BA-2026-002 | C4: BA | D4: Equipamento tecnológico | E4: Impressoras multifuncionais | F4: Impressão e digitalização de documentos administrativos. | G4: un | H4: 2 | I4: 4500 | J4: Repasse | K4: 9000 | L4: Capital | M4: Sim | N4: Preenchimento simulado; revisar especificações no plano de trabalho definitivo.
A5: BA-2026-002-04 | B5: BA-2026-002 | C5: BA | D5: Equipamento tecnológico | E5: Scanners de documentos | F5: Digitalização de documentos e correspondências físicas. | G5: un | H5: 2 | I5: 3200 | J5: Repasse | K5: 6400 | L5: Capital | M5: Sim | N5: Preenchimento simulado; revisar especificações no plano de trabalho definitivo.
A6: BA-2026-002-05 | B6: BA-2026-002 | C6: BA | D6: Equipamento tecnológico | E6: Nobreaks | F6: Proteção elétrica dos equipamentos de atendimento. | G6: un | H6: 8 | I6: 900 | J6: Repasse | K6: 7200 | L6: Capital | M6: Sim | N6: Preenchimento simulado; revisar especificações no plano de trabalho definitivo.
A7: BA-2026-002-06 | B7: BA-2026-002 | C7: BA | D7: Mobiliário | E7: Mesas e cadeiras de atendimento | F7: Mobiliário para postos de atendimento e análise. | G7: un | H7: 8 | I7: 2300 | J7: Repasse | K7: 18400 | L7: Capital | M7: Sim | N7: Preenchimento simulado; revisar especificações no plano de trabalho definitivo.
A8: BA-2026-002-07 | B8: BA-2026-002 | C8: BA | D8: Mobiliário | E8: Armários e arquivos físicos | F8: Organização de documentos e materiais da ouvidoria. | G8: un | H8: 4 | I8: 1600 | J8: Repasse | K8: 6400 | L8: Capital | M8: Sim | N8: Preenchimento simulado; revisar especificações no plano de trabalho definitivo.
A9: BA-2026-002-08 | B9: BA-2026-002 | C9: BA | D9: Equipamento tecnológico | E9: Equipamentos de sala reservada | F9: Headsets, webcams, microfones e dispositivos auxiliares para atendimento reservado. | G9: lote | H9: 1 | I9: 15800 | J9: Repasse | K9: 15800 | L9: Capital | M9: Sim | N9: Preenchimento simulado; revisar especificações no plano de trabalho definitivo.
A10: BA-2026-002-09 | B10: BA-2026-002 | C10: BA | D10: Mobiliário e aparelhamento complementar | E10: Conjunto complementar de aparelhamento da ouvidoria | F10: Mobiliário modular, sinalização interna, suporte a equipamentos e itens complementares compatíveis com o diagnóstico local, sem obras ou reformas. | G10: lote | H10: 1 | I10: 85200 | J10: Repasse/Contrapartida | K10: 85200 | L10: Capital | M10: Sim | N10: Preenchimento simulado; revisar especificações no plano de trabalho definitivo.

Sheet Plano_CE
A1: ID_Item | B1: ID_Proposta | C1: UF | D1: Categoria | E1: Item | F1: Descrição detalhada | G1: Unidade | H1: Quantidade | I1: Valor Unitário | J1: Fonte | K1: Valor Total | L1: Natureza | M1: Elegível? | N1: Observação
A2: CE-2026-003-01 | B2: CE-2026-003 | C2: CE | D2: Equipamento tecnológico | E2: Notebooks | F2: Equipamentos para tratamento de manifestações, atendimento e relatórios. | G2: un | H2: 7 | I2: 5800 | J2: Repasse | K2: 40600 | L2: Capital | M2: Sim | N2: Preenchimento simulado; revisar especificações no plano de trabalho definitivo.
A3: CE-2026-003-02 | B3: CE-2026-003 | C3: CE | D3: Equipamento tecnológico | E3: Computadores desktop/all-in-one | F3: Estações de trabalho para equipe da ouvidoria. | G3: un | H3: 5 | I3: 5200 | J3: Repasse | K3: 26000 | L3: Capital | M3: Sim | N3: Preenchimento simulado; revisar especificações no plano de trabalho definitivo.
A4: CE-2026-003-03 | B4: CE-2026-003 | C4: CE | D4: Equipamento tecnológico | E4: Impressoras multifuncionais | F4: Impressão e digitalização de documentos administrativos. | G4: un | H4: 2 | I4: 4500 | J4: Repasse | K4: 9000 | L4: Capital | M4: Sim | N4: Preenchimento simulado; revisar especificações no plano de trabalho definitivo.
A5: CE-2026-003-04 | B5: CE-2026-003 | C5: CE | D5: Equipamento tecnológico | E5: Scanners de documentos | F5: Digitalização de documentos e correspondências físicas. | G5: un | H5: 2 | I5: 3200 | J5: Repasse | K5: 6400 | L5: Capital | M5: Sim | N5: Preenchimento simulado; revisar especificações no plano de trabalho definitivo.
A6: CE-2026-003-05 | B6: CE-2026-003 | C6: CE | D6: Equipamento tecnológico | E6: Nobreaks | F6: Proteção elétrica dos equipamentos de atendimento. | G6: un | H6: 8 | I6: 900 | J6: Repasse | K6: 7200 | L6: Capital | M6: Sim | N6: Preenchimento simulado; revisar especificações no plano de trabalho definitivo.
A7: CE-2026-003-06 | B7: CE-2026-003 | C7: CE | D7: Mobiliário | E7: Mesas e cadeiras de atendimento | F7: Mobiliário para postos de atendimento e análise. | G7: un | H7: 8 | I7: 2300 | J7: Repasse | K7: 18400 | L7: Capital | M7: Sim | N7: Preenchimento simulado; revisar especificações no plano de trabalho definitivo.
A8: CE-2026-003-07 | B8: CE-2026-003 | C8: CE | D8: Mobiliário | E8: Armários e arquivos físicos | F8: Organização de documentos e materiais da ouvidoria. | G8: un | H8: 4 | I8: 1600 | J8: Repasse | K8: 6400 | L8: Capital | M8: Sim | N8: Preenchimento simulado; revisar especificações no plano de trabalho definitivo.
A9: CE-2026-003-08 | B9: CE-2026-003 | C9: CE | D9: Equipamento tecnológico | E9: Equipamentos de sala reservada | F9: Headsets, webcams, microfones e dispositivos auxiliares para atendimento reservado. | G9: lote | H9: 1 | I9: 15800 | J9: Repasse | K9: 15800 | L9: Capital | M9: Sim | N9: Preenchimento simulado; revisar especificações no plano de trabalho definitivo.
A10: CE-2026-003-09 | B10: CE-2026-003 | C10: CE | D10: Mobiliário e aparelhamento complementar | E10: Conjunto complementar de aparelhamento da ouvidoria | F10: Mobiliário modular, sinalização interna, suporte a equipamentos e itens complementares compatíveis com o diagnóstico local, sem obras ou reformas. | G10: lote | H10: 1 | I10: 80200 | J10: Repasse/Contrapartida | K10: 80200 | L10: Capital | M10: Sim | N10: Preenchimento simulado; revisar especificações no plano de trabalho definitivo.

Sheet Plano_DF
A1: ID_Item | B1: ID_Proposta | C1: UF | D1: Categoria | E1: Item | F1: Descrição detalhada | G1: Unidade | H1: Quantidade | I1: Valor Unitário | J1: Fonte | K1: Valor Total | L1: Natureza | M1: Elegível? | N1: Observação
A2: DF-2026-004-01 | B2: DF-2026-004 | C2: DF | D2: Equipamento tecnológico | E2: Notebooks | F2: Equipamentos para tratamento de manifestações, atendimento e relatórios. | G2: un | H2: 7 | I2: 5800 | J2: Repasse | K2: 40600 | L2: Capital | M2: Sim | N2: Preenchimento simulado; revisar especificações no plano de trabalho definitivo.
A3: DF-2026-004-02 | B3: DF-2026-004 | C3: DF | D3: Equipamento tecnológico | E3: Computadores desktop/all-in-one | F3: Estações de trabalho para equipe da ouvidoria. | G3: un | H3: 5 | I3: 5200 | J3: Repasse | K3: 26000 | L3: Capital | M3: Sim | N3: Preenchimento simulado; revisar especificações no plano de trabalho definitivo.
A4: DF-2026-004-03 | B4: DF-2026-004 | C4: DF | D4: Equipamento tecnológico | E4: Impressoras multifuncionais | F4: Impressão e digitalização de documentos administrativos. | G4: un | H4: 2 | I4: 4500 | J4: Repasse | K4: 9000 | L4: Capital | M4: Sim | N4: Preenchimento simulado; revisar especificações no plano de trabalho definitivo.
A5: DF-2026-004-04 | B5: DF-2026-004 | C5: DF | D5: Equipamento tecnológico | E5: Scanners de documentos | F5: Digitalização de documentos e correspondências físicas. | G5: un | H5: 2 | I5: 3200 | J5: Repasse | K5: 6400 | L5: Capital | M5: Sim | N5: Preenchimento simulado; revisar especificações no plano de trabalho definitivo.
A6: DF-2026-004-05 | B6: DF-2026-004 | C6: DF | D6: Equipamento tecnológico | E6: Nobreaks | F6: Proteção elétrica dos equipamentos de atendimento. | G6: un | H6: 8 | I6: 900 | J6: Repasse | K6: 7200 | L6: Capital | M6: Sim | N6: Preenchimento simulado; revisar especificações no plano de trabalho definitivo.
A7: DF-2026-004-06 | B7: DF-2026-004 | C7: DF | D7: Mobiliário | E7: Mesas e cadeiras de atendimento | F7: Mobiliário para postos de atendimento e análise. | G7: un | H7: 8 | I7: 2300 | J7: Repasse | K7: 18400 | L7: Capital | M7: Sim | N7: Preenchimento simulado; revisar especificações no plano de trabalho definitivo.
A8: DF-2026-004-07 | B8: DF-2026-004 | C8: DF | D8: Mobiliário | E8: Armários e arquivos físicos | F8: Organização de documentos e materiais da ouvidoria. | G8: un | H8: 4 | I8: 1600 | J8: Repasse | K8: 6400 | L8: Capital | M8: Sim | N8: Preenchimento simulado; revisar especificações no plano de trabalho definitivo.
A9: DF-2026-004-08 | B9: DF-2026-004 | C9: DF | D9: Equipamento tecnológico | E9: Equipamentos de sala reservada | F9: Headsets, webcams, microfones e dispositivos auxiliares para atendimento reservado. | G9: lote | H9: 1 | I9: 15800 | J9: Repasse | K9: 15800 | L9: Capital | M9: Sim | N9: Preenchimento simulado; revisar especificações no plano de trabalho definitivo.
A10: DF-2026-004-09 | B10: DF-2026-004 | C10: DF | D10: Mobiliário e aparelhamento complementar | E10: Conjunto complementar de aparelhamento da ouvidoria | F10: Mobiliário modular, sinalização interna, suporte a equipamentos e itens complementares compatíveis com o diagnóstico local, sem obras ou reformas. | G10: lote | H10: 1 | I10: 95200 | J10: Repasse/Contrapartida | K10: 95200 | L10: Capital | M10: Sim | N10: Preenchimento simulado; revisar especificações no plano de trabalho definitivo.

Sheet Plano_ES
A1: ID_Item | B1: ID_Proposta | C1: UF | D1: Categoria | E1: Item | F1: Descrição detalhada | G1: Unidade | H1: Quantidade | I1: Valor Unitário | J1: Fonte | K1: Valor Total | L1: Natureza | M1: Elegível? | N1: Observação
A2: ES-2026-005-01 | B2: ES-2026-005 | C2: ES | D2: Equipamento tecnológico | E2: Notebooks | F2: Equipamentos para tratamento de manifestações, atendimento e relatórios. | G2: un | H2: 7 | I2: 5800 | J2: Repasse | K2: 40600 | L2: Capital | M2: Sim | N2: Preenchimento simulado; revisar especificações no plano de trabalho definitivo.
A3: ES-2026-005-02 | B3: ES-2026-005 | C3: ES | D3: Equipamento tecnológico | E3: Computadores desktop/all-in-one | F3: Estações de trabalho para equipe da ouvidoria. | G3: un | H3: 5 | I3: 5200 | J3: Repasse | K3: 26000 | L3: Capital | M3: Sim | N3: Preenchimento simulado; revisar especificações no plano de trabalho definitivo.
A4: ES-2026-005-03 | B4: ES-2026-005 | C4: ES | D4: Equipamento tecnológico | E4: Impressoras multifuncionais | F4: Impressão e digitalização de documentos administrativos. | G4: un | H4: 2 | I4: 4500 | J4: Repasse | K4: 9000 | L4: Capital | M4: Sim | N4: Preenchimento simulado; revisar especificações no plano de trabalho definitivo.
A5: ES-2026-005-04 | B5: ES-2026-005 | C5: ES | D5: Equipamento tecnológico | E5: Scanners de documentos | F5: Digitalização de documentos e correspondências físicas. | G5: un | H5: 2 | I5: 3200 | J5: Repasse | K5: 6400 | L5: Capital | M5: Sim | N5: Preenchimento simulado; revisar especificações no plano de trabalho definitivo.
A6: ES-2026-005-05 | B6: ES-2026-005 | C6: ES | D6: Equipamento tecnológico | E6: Nobreaks | F6: Proteção elétrica dos equipamentos de atendimento. | G6: un | H6: 8 | I6: 900 | J6: Repasse | K6: 7200 | L6: Capital | M6: Sim | N6: Preenchimento simulado; revisar especificações no plano de trabalho definitivo.
A7: ES-2026-005-06 | B7: ES-2026-005 | C7: ES | D7: Mobiliário | E7: Mesas e cadeiras de atendimento | F7: Mobiliário para postos de atendimento e análise. | G7: un | H7: 8 | I7: 2300 | J7: Repasse | K7: 18400 | L7: Capital | M7: Sim | N7: Preenchimento simulado; revisar especificações no plano de trabalho definitivo.
A8: ES-2026-005-07 | B8: ES-2026-005 | C8: ES | D8: Mobiliário | E8: Armários e arquivos físicos | F8: Organização de documentos e materiais da ouvidoria. | G8: un | H8: 4 | I8: 1600 | J8: Repasse | K8: 6400 | L8: Capital | M8: Sim | N8: Preenchimento simulado; revisar especificações no plano de trabalho definitivo.
A9: ES-2026-005-08 | B9: ES-2026-005 | C9: ES | D9: Equipamento tecnológico | E9: Equipamentos de sala reservada | F9: Headsets, webcams, microfones e dispositivos auxiliares para atendimento reservado. | G9: lote | H9: 1 | I9: 15800 | J9: Repasse | K9: 15800 | L9: Capital | M9: Sim | N9: Preenchimento simulado; revisar especificações no plano de trabalho definitivo.
